Workbook

Sheet Başlangıç
A1: SUPERHERO ANTRENMAN PROGRAMI
A2: Cinsiyet 👉 | B2: erkek | D2: ⚠️ Satın alınan program yalnızca satın alan kişinin kullanımı içindir. Superhero kitabı, erişim sertifikası ve antrenman excel dosyasının; yayıncının izni olmadan paylaşılması, internete yüklenmesi ve dağıtılması yasaktır ve yasalarca cezalandırılır. Copyright ©2024 Fit Yemek - www.fityemek.com
A3: Vücut ağırlığı 👉 | B3: 78.8
B5: 1 tekrar max hesabı için yapabildiğin ağırlık ve tekrar sayılarını gir 👇 | E5: bunlar başlangıç ağırlıkların olacak 👇 | F5: bunları senin için ayarladık, konu hakkında derin bilgiye sahip değilsen dokunma! 👇
A6: G1 | B6: ağırlık | C6: tekrar sayısı | D6: 1 tekrar max | E6: başlangıç ağırlıkları | F6: haftalık artış | G6: RPE | H6: set x tekrar sayıları
A7: Bench Press | B7: 10 | C7: 12 | D7: =(B7*C7*0.0333)+B7 -> 13.996 | E7: =MROUND((D7*0.85*0.8),2.5) -> 10 | F7: 2.5 | H7: 4x5+
A8: Squat | B8: 20 | C8: 5 | D8: =(B8*C8*0.0333)+B8 -> 23.33 | E8: =MROUND((D8*0.85*0.7),2.5) -> 15 | F8: 5 | H8: 4x5+
A9: Over Head Press | B9: 25 | C9: 4 | D9: =(B9*C9*0.0333)+B9 -> 28.33 | E9: =MROUND((D9*0.85*0.7),2.5) -> 17.5 | F9: 2.5 | H9: 4x5+
A11: G2
A12: DB Shoulder Press | B12: 10 | C12: 9 | D12: =(B12*C12*0.0333)+B12 -> 12.997 | E12: =MROUND((D12*0.85*0.6),2.5) -> 7.5 | F12: 2.5 | H12: 3x10
A13: Dumbbell Romanian Deadlift | B13: 12.5 | C13: 13 | D13: =(B13*C13*0.0333)+B13 -> 17.91125 | E13: =MROUND((D13*0.85*0.6),2.5) -> 10 | F13: 5 | H13: 3x8
A14: Bench Press | B14: 10 | C14: 12 | D14: =(B14*C14*0.0333)+B14 -> 13.996 | E14: =MROUND((D14*0.85*0.6),2.5) -> 7.5 | F14: 2.5 | H14: 3x10
A15: Barbell Row | B15: 30 | C15: 6 | D15: =(B15*C15*0.0333)+B15 -> 35.994 | E15: =MROUND((D15*0.85*0.6),2.5) -> 17.5 | F15: 2.5 | H15: 4x10
A16: Squat | B16: 20 | C16: 5 | D16: =(B16*C16*0.0333)+B16 -> 23.33 | E16: =MROUND((D16*0.85*0.6),2.5) -> 12.5 | F16: 2.5 | H16: 3x10
A17: Negative Pull Ups | E17: vücut a. | G17: 9 | H17: 3xmax
A19: G3
A20: Lateral Raises | B20: 5 | C20: 10 | D20: =(B20*C20*0.0333)+B20 -> 6.665 | E20: =MROUND((D20*0.85*0.6),2.5) -> 2.5 | F20: 5 | G20: 9 | H20: 3x10-14
A21: Lat Pulldown | B21: 35 | C21: 12 | D21: =(B21*C21*0.0333)+B21 -> 48.986 | E21: =MROUND((D21*0.85*0.65),2.5) -> 27.5 | F21: 5 | G21: 8 | H21: 3x10-14
A22: Chest Fly Machine | B22: 40 | C22: 7 | D22: =(B22*C22*0.0333)+B22 -> 49.324 | E22: =MROUND((D22*0.85*0.65),2.5) -> 27.5 | F22: 5 | G22: 8 | H22: 3x10-14
A23: Dumbbell Lunges | B23: 7.5 | C23: 8 | D23: =(B23*C23*0.0333)+B23 -> 9.498 | E23: =MROUND((D23*0.85*0.65),2.5) -> 5 | F23: 5 | G23: 9 | H23: 3x10-14
A25: G4
A26: Overhead Triceps Extension | B26: 20 | C26: 4 | D26: =(B26*C26*0.0333)+B26 -> 22.664 | E26: =MROUND((D26*0.85*0.75),2.5) -> 15 | F26: 5 | G26: 9 | H26: 3x8-12
A27: Incline Dumbbell Curl | B27: 5 | C27: 10 | D27: =(B27*C27*0.0333)+B27 -> 6.665 | E27: =MROUND((D27*0.85*0.75),2.5) -> 5 | F27: 5 | G27: 9 | H27: 3x8-12
A28: Crunch | E28: vücut a. | G28: 9 | H28: 3xmax
A29: Leg Raises | E29: vücut a. | G29: 9 | H29: 3xmax
A30: Deadbug | E30: vücut a. | G30: 9 | H30: 3xmax
A32: G5
A33: Push-Up

Sheet Hafta 1
A1: Vücut ağırlığı 👉 | B1: ='Başlangıç'!$B$3 -> 78.8
A3: WORKOUT A | C3: 1 tekrar max tahmini 👉 | G3: =A5 -> Bench Press | I3: =MROUND((IF(J5="","",SUM((B5*(MAX(H5,I5,J5,K5))*0.0333)+B5))), 0.5) -> 11.5
A4: Egzersiz | B4: Kg | C4: Set x Tekrar | D4: RPE | E4: Isınma setleri | H4: Set 1 | I4: Set 2 | J4: Set 3 | K4: Set 4 | L4: Notlar
A5: ='Başlangıç'!$A$7 -> Bench Press | B5: ='Başlangıç'!$E$7 -> 10 | C5: ='Başlangıç'!$H$7 -> 4x5+ | D5: ='Başlangıç'!$G$7 | E5: =MROUND((B5*0.6),2.5) -> 5 | F5: =MROUND((B5*0.7),2.5) -> 7.5 | G5: =MROUND((B5*0.85),2.5) -> 7.5 | H5: 5 | I5: 5 | J5: 5 | K5: 5 | L5: tek plaka ağırlığı 15kg bar ağırlığı hariç | M5: 👈 bu alanı not tutmak için kullanabilirsin
A6: ='Başlangıç'!$A$12 -> DB Shoulder Press | B6: ='Başlangıç'!$E$12 -> 7.5 | C6: ='Başlangıç'!$H$12 -> 3x10 | D6: ='Başlangıç'!$G$12 | E6: =MROUND((B6*0.6),2.5) -> 5 | F6: =MROUND((B6*0.85),2.5) -> 7.5 | G6: - | H6: 8 | I6: 7 | J6: 5 | L6: tek dumbbell ağırlığı
A7: ='Başlangıç'!$A$13 -> Dumbbell Romanian Deadlift | B7: ='Başlangıç'!$E$13 -> 10 | C7: ='Başlangıç'!$H$13 -> 3x8 | D7: ='Başlangıç'!$G$13 | E7: =MROUND((B7*0.6),2.5) -> 5 | F7: =MROUND((B7*0.85),2.5) -> 7.5 | G7: - | H7: 8 | I7: 8 | J7: 8 | L7: tek dumbbell ağırlığı
A8: ='Başlangıç'!$A$21 -> Lat Pulldown | B8: ='Başlangıç'!$E$21 -> 27.5 | C8: ='Başlangıç'!$H$21 -> 3x10-14 | D8: ='Başlangıç'!$G$21 -> 8 | E8: - | F8: - | G8: - | H8: 14 | I8: 14 | J8: 15
A9: ='Başlangıç'!$A$23 -> Dumbbell Lunges | B9: ='Başlangıç'!$E$23 -> 5 | C9: ='Başlangıç'!$H$23 -> 3x10-14 | D9: ='Başlangıç'!$G$23 -> 9 | E9: - | F9: - | G9: - | H9: 12 | I9: 12 | J9: 10 | L9: tek dumbbell ağırlığı
A10: ='Başlangıç'!$A$28 -> Crunch | B10: ='Başlangıç'!$E$28 -> vücut a. | C10: ='Başlangıç'!$H$28 -> 3xmax | D10: ='Başlangıç'!$G$28 -> 9 | E10: - | F10: - | G10: - | H10: 20 | I10: 20 | J10: 20
A11: ='Başlangıç'!$A$33 -> Push-Up | H11: 5 | I11: 5 | J11: 3
A13: WORKOUT B | C13: 1 tekrar max tahmini 👉 | G13: =A15 -> Squat | I13: =MROUND((IF(J15="","",SUM((B15*(MAX(H15,I15,J15,K15))*0.0333)+B15))), 0.5) -> 18.5
A14: Egzersiz | B14: Kg | C14: Set x Tekrar | D14: RPE | E14: Isınma setleri | H14: Set 1 | I14: Set 2 | J14: Set 3 | K14: Set 4 | L14: Notlar
A15: ='Başlangıç'!$A$8 -> Squat | B15: ='Başlangıç'!$E$8 -> 15 | C15: ='Başlangıç'!$H$8 -> 4x5+ | D15: ='Başlangıç'!$G$8 | E15: =MROUND((B15*0.6),2.5) -> 10 | F15: =MROUND((B15*0.7),2.5) -> 10 | G15: =MROUND((B15*0.85),2.5) -> 12.5 | H15: 5 | I15: 5 | J15: 5 | K15: 7 | L15: tek plaka ağırlığı
A16: ='Başlangıç'!$A$14 -> Bench Press | B16: ='Başlangıç'!$E$14 -> 7.5 | C16: ='Başlangıç'!$H$14 -> 3x10 | D16: ='Başlangıç'!$G$14 | E16: =MROUND((B16*0.6),2.5) -> 5 | F16: =MROUND((B16*0.85),2.5) -> 7.5 | G16: - | H16: 10 | I16: 8 | J16: 5
A17: ='Başlangıç'!$A$17 -> Negative Pull Ups | B17: ='Başlangıç'!$E$17 -> vücut a. | C17: ='Başlangıç'!$H$17 -> 3xmax | D17: ='Başlangıç'!$G$17 -> 9 | E17: - | F17: - | G17: - | H17: - | I17: - | J17: -
A18: ='Başlangıç'!$A$20 -> Lateral Raises | B18: ='Başlangıç'!$E$20 -> 2.5 | C18: ='Başlangıç'!$H$20 -> 3x10-14 | D18: ='Başlangıç'!$G$20 -> 9 | E18: - | F18: - | G18: - | H18: 14 | I18: 14 | J18: 15
A19: ='Başlangıç'!$A$27 -> Incline Dumbbell Curl | B19: ='Başlangıç'!$E$27 -> 5 | C19: ='Başlangıç'!$H$27 -> 3x8-12 | D19: ='Başlangıç'!$G$27 -> 9 | E19: - | F19: - | G19: - | H19: 12 | I19: 12 | J19: 10
A20: ='Başlangıç'!$A$29 -> Leg Raises | B20: ='Başlangıç'!$E$29 -> vücut a. | C20: ='Başlangıç'!$H$29 -> 3xmax | D20: ='Başlangıç'!$G$29 -> 9 | E20: - | F20: - | G20: - | H20: 12 | I20: 10 | J20: 10
A23: WORKOUT C | C23: 1 tekrar max tahmini 👉 | G23: =A25 -> Over Head Press | I23: =MROUND((IF(J25="","",SUM((B25*(MAX(H25,I25,J25,K25))*0.0333)+B25))), 0.5) -> 21
A24: Egzersiz | B24: Kg | C24: Set x Tekrar | D24: RPE | E24: Isınma setleri | H24: Set 1 | I24: Set 2 | J24: Set 3 | K24: Set 4 | L24: Notlar
A25: ='Başlangıç'!$A$9 -> Over Head Press | B25: ='Başlangıç'!$E$9 -> 17.5 | C25: ='Başlangıç'!$H$9 -> 4x5+ | D25: ='Başlangıç'!$G$9 | E25: =MROUND((B25*0.6),2.5) -> 10 | F25: =MROUND((B25*0.7),2.5) -> 12.5 | G25: =MROUND((B25*0.85),2.5) -> 15 | H25: 6 | I25: 5 | J25: 5 | K25: 5
A26: ='Başlangıç'!$A$16 -> Squat | B26: ='Başlangıç'!$E$16 -> 12.5 | C26: ='Başlangıç'!$H$16 -> 3x10 | D26: ='Başlangıç'!$G$16 | E26: =MROUND((B26*0.6),2.5) -> 7.5 | F26: =MROUND((B26*0.85),2.5) -> 10 | G26: - | H26: 10 | I26: 10 | J26: 7 | L26: tek plaka ağırlığı
A27: ='Başlangıç'!$A$15 -> Barbell Row | B27: ='Başlangıç'!$E$15 -> 17.5 | C27: ='Başlangıç'!$H$15 -> 4x10 | D27: ='Başlangıç'!$G$15 | E27: =MROUND((B27*0.6),2.5) -> 10 | F27: =MROUND((B27*0.85),2.5) -> 15 | G27: - | H27: 10 | I27: 10 | J27: 10 | K27: 12
A28: ='Başlangıç'!$A$22 -> Chest Fly Machine | B28: ='Başlangıç'!$E$22 -> 27.5 | C28: ='Başlangıç'!$H$22 -> 3x10-14 | D28: ='Başlangıç'!$G$22 -> 8 | E28: - | F28: - | G28: - | H28: 14 | I28: 12 | J28: 8
A29: ='Başlangıç'!$A$26 -> Overhead Triceps Extension | B29: ='Başlangıç'!$E$26 -> 15 | C29: ='Başlangıç'!$H$26 -> 3x8-12 | D29: ='Başlangıç'!$G$26 -> 9 | E29: - | F29: - | G29: - | H29: 7 | I29: 5 | J29: 5
A30: ='Başlangıç'!$A$30 -> Deadbug | B30: ='Başlangıç'!$E$30 -> vücut a. | C30: ='Başlangıç'!$H$30 -> 3xmax | D30: ='Başlangıç'!$G$30 -> 9 | E30: - | F30: - | G30: - | H30: 10 | I30: 6 | J30: 5

Sheet Hafta 2
A1: Vücut ağırlığı 👉 | B1: 79.8
A3: WORKOUT A | C3: 1 tekrar max tahmini 👉 | G3: =A5 -> Bench Press | I3: =MROUND((IF(J5="","",SUM((B5*(MAX(H5,I5,J5,K5))*0.0333)+B5))), 0.5) -> 16 | L3: 46139
A4: Egzersiz | B4: Kg | C4: Set x Tekrar | D4: RPE | E4: Isınma setleri | H4: Set 1 | I4: Set 2 | J4: Set 3 | K4: Set 4 | L4: Notlar
A5: ='Başlangıç'!$A$7 -> Bench Press | B5: =IF('Hafta 1'!$K$5>=5,(('Hafta 1'!$B$5)+('Başlangıç'!$F$7)),MROUND(('Hafta 1'!$B$5*0.9),2.5)) -> 12.5 | C5: ='Başlangıç'!$H$7 -> 4x5+ | D5: ='Başlangıç'!$G$7 | E5: =MROUND((B5*0.6),2.5) -> 7.5 | F5: =MROUND((B5*0.7),2.5) -> 10 | G5: =MROUND((B5*0.85),2.5) -> 10 | H5: 5 | I5: 5 | J5: 5 | K5: 8 | M5: 👈 bu alanı not tutmak için kullanabilirsin
A6: ='Başlangıç'!$A$12 -> DB Shoulder Press | B6: =IF('Hafta 1'!$J$6=10,(('Hafta 1'!$B$6)+('Başlangıç'!$F$12)),MROUND(('Hafta 1'!$B$6*0.9),2.5)) -> 7.5 | C6: ='Başlangıç'!$H$12 -> 3x10 | D6: ='Başlangıç'!$G$12 | E6: =MROUND((B6*0.6),2.5) -> 5 | F6: =MROUND((B6*0.85),2.5) -> 7.5 | G6: - | H6: 10 | I6: 8 | J6: 8
A7: ='Başlangıç'!$A$13 -> Dumbbell Romanian Deadlift | B7: =IF('Hafta 1'!$J$7=8,(('Hafta 1'!$B$7)+('Başlangıç'!$F$13)),MROUND(('Hafta 1'!$B$7*0.9),2.5)) -> 15 | C7: ='Başlangıç'!$H$13 -> 3x8 | D7: ='Başlangıç'!$G$13 | E7: =MROUND((B7*0.6),2.5) -> 10 | F7: =MROUND((B7*0.85),2.5) -> 12.5 | G7: - | H7: 8 | I7: 8 | J7: 8
A8: ='Başlangıç'!$A$21 -> Lat Pulldown | B8: =IF('Hafta 1'!$H$8+'Hafta 1'!$I$8+'Hafta 1'!$J$8>=42,'Hafta 1'!$B$8+'Başlangıç'!$F$21,'Hafta 1'!$B$8) -> 32.5 | C8: ='Başlangıç'!$H$21 -> 3x10-14 | D8: ='Başlangıç'!$G$21 -> 8 | E8: - | F8: - | G8: - | H8: 14 | I8: 14 | J8: 12
A9: ='Başlangıç'!$A$23 -> Dumbbell Lunges | B9: =IF('Hafta 1'!$H$9+'Hafta 1'!$I$9+'Hafta 1'!$J$9>=42,'Hafta 1'!$B$9+'Başlangıç'!$F$23,'Hafta 1'!$B$9) -> 5 | C9: ='Başlangıç'!$H$23 -> 3x10-14 | D9: ='Başlangıç'!$G$23 -> 9 | E9: - | F9: - | G9: - | H9: 14 | I9: 14 | J9: 14
A10: ='Başlangıç'!$A$28 -> Crunch | B10: ='Başlangıç'!$E$28 -> vücut a. | C10: ='Başlangıç'!$H$28 -> 3xmax | D10: ='Başlangıç'!$G$28 -> 9 | E10: - | F10: - | G10: - | H10: 30 | I10: 32 | J10: 30
A11: Push Ups | H11: 7 | I11: 5 | J11: 3
A13: WORKOUT B | C13: 1 tekrar max tahmini 👉 | G13: =A15 -> Squat | I13: =MROUND((IF(J15="","",SUM((B15*(MAX(H15,I15,J15,K15))*0.0333)+B15))), 0.5) -> 24.5 | L13: 46141
A14: Egzersiz | B14: Kg | C14: Set x Tekrar | D14: RPE | E14: Isınma setleri | H14: Set 1 | I14: Set 2 | J14: Set 3 | K14: Set 4 | L14: Notlar
A15: ='Başlangıç'!$A$8 -> Squat | B15: =IF('Hafta 1'!$K$15>=5,(('Hafta 1'!$B$15)+('Başlangıç'!$F$8)),MROUND(('Hafta 1'!$B$15*0.9),2.5)) -> 20 | C15: ='Başlangıç'!$H$8 -> 4x5+ | D15: ='Başlangıç'!$G$8 | E15: =MROUND((B15*0.6),2.5) -> 12.5 | F15: =MROUND((B15*0.7),2.5) -> 15 | G15: =MROUND((B15*0.85),2.5) -> 17.5 | H15: 5 | I15: 5 | J15: 5 | K15: 7
A16: ='Başlangıç'!$A$14 -> Bench Press | B16: =IF('Hafta 1'!$J$16=10,(('Hafta 1'!$B$16)+('Başlangıç'!$F$14)),MROUND(('Hafta 1'!$B$16*0.9),2.5)) -> 7.5 | C16: ='Başlangıç'!$H$14 -> 3x10 | D16: ='Başlangıç'!$G$14 | E16: =MROUND((B16*0.6),2.5) -> 5 | F16: =MROUND((B16*0.85),2.5) -> 7.5 | G16: - | H16: 10 | I16: 10 | J16: 10
A17: ='Başlangıç'!$A$17 -> Negative Pull Ups | B17: ='Başlangıç'!$E$17 -> vücut a. | C17: ='Başlangıç'!$H$17 -> 3xmax | D17: ='Başlangıç'!$G$17 -> 9 | E17: - | F17: - | G17: -
A18: ='Başlangıç'!$A$20 -> Lateral Raises | B18: 5 | C18: ='Başlangıç'!$H$20 -> 3x10-14 | D18: ='Başlangıç'!$G$20 -> 9 | E18: - | F18: - | G18: - | H18: 13 | I18: 12 | J18: 9
A19: ='Başlangıç'!$A$27 -> Incline Dumbbell Curl | B19: =IF('Hafta 1'!$H$19+'Hafta 1'!$I$19+'Hafta 1'!$J$19>=36,'Hafta 1'!$B$19+'Başlangıç'!$F$27,'Hafta 1'!$B$19) -> 5 | C19: ='Başlangıç'!$H$27 -> 3x8-12 | D19: ='Başlangıç'!$G$27 -> 9 | E19: - | F19: - | G19: - | H19: 11 | I19: 8 | J19: 6
A20: ='Başlangıç'!$A$29 -> Leg Raises | B20: ='Başlangıç'!$E$29 -> vücut a. | C20: ='Başlangıç'!$H$29 -> 3xmax | D20: ='Başlangıç'!$G$29 -> 9 | E20: - | F20: - | G20: - | H20: 17 | I20: 17 | J20: 13
A23: WORKOUT C | C23: 1 tekrar max tahmini 👉 | G23: =A25 -> Over Head Press | I23: =MROUND((IF(J25="","",SUM((B25*(MAX(H25,I25,J25,K25))*0.0333)+B25))), 0.5) -> 0
A24: Egzersiz | B24: Kg | C24: Set x Tekrar | D24: RPE | E24: Isınma setleri | H24: Set 1 | I24: Set 2 | J24: Set 3 | K24: Set 4 | L24: Notlar
A25: ='Başlangıç'!$A$9 -> Over Head Press | B25: =IF('Hafta 1'!$K$25>=5,(('Hafta 1'!$B$25)+('Başlangıç'!$F$9)),MROUND(('Hafta 1'!$B$25*0.9),2.5)) -> 20 | C25: ='Başlangıç'!$H$9 -> 4x5+ | D25: ='Başlangıç'!$G$9 | E25: =MROUND((B25*0.6),2.5) -> 12.5 | F25: =MROUND((B25*0.7),2.5) -> 15 | G25: =MROUND((B25*0.85),2.5) -> 17.5
A26: ='Başlangıç'!$A$16 -> Squat | B26: =IF('Hafta 1'!$J$26=10,(('Hafta 1'!$B$26)+('Başlangıç'!$F$16)),MROUND(('Hafta 1'!$B$26*0.9),2.5)) -> 12.5 | C26: ='Başlangıç'!$H$16 -> 3x10 | D26: ='Başlangıç'!$G$16 | E26: =MROUND((B26*0.6),2.5) -> 7.5 | F26: =MROUND((B26*0.85),2.5) -> 10 | G26: -
A27: ='Başlangıç'!$A$15 -> Barbell Row | B27: =IF('Hafta 1'!$K$27=10,(('Hafta 1'!$B$27)+('Başlangıç'!$F$15)),MROUND(('Hafta 1'!$B$27*0.9),2.5)) -> 15 | C27: ='Başlangıç'!$H$15 -> 4x10 | D27: ='Başlangıç'!$G$15 | E27: =MROUND((B27*0.6),2.5) -> 10 | F27: =MROUND((B27*0.85),2.5) -> 12.5 | G27: -
A28: ='Başlangıç'!$A$22 -> Chest Fly Machine | B28: =IF('Hafta 1'!$H$28+'Hafta 1'!$I$28+'Hafta 1'!$J$28>=42,'Hafta 1'!$B$28+'Başlangıç'!$F$22,'Hafta 1'!$B$28) -> 27.5 | C28: ='Başlangıç'!$H$22 -> 3x10-14 | D28: ='Başlangıç'!$G$22 -> 8 | E28: - | F28: - | G28: -
A29: ='Başlangıç'!$A$26 -> Overhead Triceps Extension | B29: =IF('Hafta 1'!$H$29+'Hafta 1'!$I$29+'Hafta 1'!$J$29>=36,'Hafta 1'!$B$29+'Başlangıç'!$F$26,'Hafta 1'!$B$29) -> 15 | C29: ='Başlangıç'!$H$26 -> 3x8-12 | D29: ='Başlangıç'!$G$26 -> 9 | E29: - | F29: - | G29: -
A30: ='Başlangıç'!$A$30 -> Deadbug | B30: ='Başlangıç'!$E$30 -> vücut a. | C30: ='Başlangıç'!$H$30 -> 3xmax | D30: ='Başlangıç'!$G$30 -> 9 | E30: - | F30: - | G30: -

Sheet Hafta 3
A1: Vücut ağırlığı 👉 | B1: ='Başlangıç'!$B$3 -> 78.8
A3: WORKOUT A | C3: 1 tekrar max tahmini 👉 | G3: =A5 -> Bench Press | I3: =MROUND((IF(J5="","",SUM((B5*(MAX(H5,I5,J5,K5))*0.0333)+B5))), 0.5) -> 0
A4: Egzersiz | B4: Kg | C4: Set x Tekrar | D4: RPE | E4: Isınma setleri | H4: Set 1 | I4: Set 2 | J4: Set 3 | K4: Set 4 | L4: Notlar
A5: ='Başlangıç'!$A$7 -> Bench Press | B5: =IF('Hafta 2'!$K$5>=5,(('Hafta 2'!$B$5)+('Başlangıç'!$F$7)),MROUND(('Hafta 2'!$B$5*0.9),2.5)) -> 15 | C5: ='Başlangıç'!$H$7 -> 4x5+ | D5: ='Başlangıç'!$G$7 | E5: =MROUND((B5*0.6),2.5) -> 10 | F5: =MROUND((B5*0.7),2.5) -> 10 | G5: =MROUND((B5*0.85),2.5) -> 12.5 | M5: 👈 bu alanı not tutmak için kullanabilirsin
A6: ='Başlangıç'!$A$12 -> DB Shoulder Press | B6: =IF('Hafta 2'!$J$6=10,(('Hafta 2'!$B$6)+('Başlangıç'!$F$12)),MROUND(('Hafta 2'!$B$6*0.9),2.5)) -> 7.5 | C6: ='Başlangıç'!$H$12 -> 3x10 | D6: ='Başlangıç'!$G$12 | E6: =MROUND((B6*0.6),2.5) -> 5 | F6: =MROUND((B6*0.85),2.5) -> 7.5 | G6: -
A7: ='Başlangıç'!$A$13 -> Dumbbell Romanian Deadlift | B7: =IF('Hafta 2'!$J$7=8,(('Hafta 2'!$B$7)+('Başlangıç'!$F$13)),MROUND(('Hafta 2'!$B$7*0.9),2.5)) -> 20 | C7: ='Başlangıç'!$H$13 -> 3x8 | D7: ='Başlangıç'!$G$13 | E7: =MROUND((B7*0.6),2.5) -> 12.5 | F7: =MROUND((B7*0.85),2.5) -> 17.5 | G7: -
A8: ='Başlangıç'!$A$21 -> Lat Pulldown | B8: =IF('Hafta 2'!$H$8+'Hafta 2'!$I$8+'Hafta 2'!$J$8>=42,'Hafta 2'!$B$8+'Başlangıç'!$F$21,'Hafta 2'!$B$8) -> 32.5 | C8: ='Başlangıç'!$H$21 -> 3x10-14 | D8: ='Başlangıç'!$G$21 -> 8 | E8: - | F8: - | G8: -
A9: ='Başlangıç'!$A$23 -> Dumbbell Lunges | B9: =IF('Hafta 2'!$H$9+'Hafta 2'!$I$9+'Hafta 2'!$J$9>=42,'Hafta 2'!$B$9+'Başlangıç'!$F$23,'Hafta 2'!$B$9) -> 10 | C9: ='Başlangıç'!$H$23 -> 3x10-14 | D9: ='Başlangıç'!$G$23 -> 9 | E9: - | F9: - | G9: -
A10: ='Başlangıç'!$A$28 -> Crunch | B10: ='Başlangıç'!$E$28 -> vücut a. | C10: ='Başlangıç'!$H$28 -> 3xmax | D10: ='Başlangıç'!$G$28 -> 9 | E10: - | F10: - | G10: -
H11: 👆 her set için yaptığın tekrar sayılarını gir
A13: WORKOUT B | C13: 1 tekrar max tahmini 👉 | G13: =A15 -> Squat | I13: =MROUND((IF(J15="","",SUM((B15*(MAX(H15,I15,J15,K15))*0.0333)+B15))), 0.5) -> 0
A14: Egzersiz | B14: Kg | C14: Set x Tekrar | D14: RPE | E14: Isınma setleri | H14: Set 1 | I14: Set 2 | J14: Set 3 | K14: Set 4 | L14: Notlar
A15: ='Başlangıç'!$A$8 -> Squat | B15: =IF('Hafta 2'!$K$15>=5,(('Hafta 2'!$B$15)+('Başlangıç'!$F$8)),MROUND(('Hafta 2'!$B$15*0.9),2.5)) -> 25 | C15: ='Başlangıç'!$H$8 -> 4x5+ | D15: ='Başlangıç'!$G$8 | E15: =MROUND((B15*0.6),2.5) -> 15 | F15: =MROUND((B15*0.7),2.5) -> 17.5 | G15: =MROUND((B15*0.85),2.5) -> 22.5
A16: ='Başlangıç'!$A$14 -> Bench Press | B16: =IF('Hafta 2'!$J$16=10,(('Hafta 2'!$B$16)+('Başlangıç'!$F$14)),MROUND(('Hafta 2'!$B$16*0.9),2.5)) -> 10 | C16: ='Başlangıç'!$H$14 -> 3x10 | D16: ='Başlangıç'!$G$14 | E16: =MROUND((B16*0.6),2.5) -> 5 | F16: =MROUND((B16*0.85),2.5) -> 7.5 | G16: -
A17: ='Başlangıç'!$A$17 -> Negative Pull Ups | B17: ='Başlangıç'!$E$17 -> vücut a. | C17: ='Başlangıç'!$H$17 -> 3xmax | D17: ='Başlangıç'!$G$17 -> 9 | E17: - | F17: - | G17: -
A18: ='Başlangıç'!$A$20 -> Lateral Raises | B18: =IF('Hafta 2'!$H$18+'Hafta 2'!$I$18+'Hafta 2'!$J$18>=42,'Hafta 2'!$B$18+'Başlangıç'!$F$20,'Hafta 2'!$B$18) -> 5 | C18: ='Başlangıç'!$H$20 -> 3x10-14 | D18: ='Başlangıç'!$G$20 -> 9 | E18: - | F18: - | G18: -
A19: ='Başlangıç'!$A$27 -> Incline Dumbbell Curl | B19: =IF('Hafta 2'!$H$19+'Hafta 2'!$I$19+'Hafta 2'!$J$19>=36,'Hafta 2'!$B$19+'Başlangıç'!$F$27,'Hafta 2'!$B$19) -> 5 | C19: ='Başlangıç'!$H$27 -> 3x8-12 | D19: ='Başlangıç'!$G$27 -> 9 | E19: - | F19: - | G19: -
A20: ='Başlangıç'!$A$29 -> Leg Raises | B20: ='Başlangıç'!$E$29 -> vücut a. | C20: ='Başlangıç'!$H$29 -> 3xmax | D20: ='Başlangıç'!$G$29 -> 9 | E20: - | F20: - | G20: -
A23: WORKOUT C | C23: 1 tekrar max tahmini 👉 | G23: =A25 -> Over Head Press | I23: =MROUND((IF(J25="","",SUM((B25*(MAX(H25,I25,J25,K25))*0.0333)+B25))), 0.5) -> 0
A24: Egzersiz | B24: Kg | C24: Set x Tekrar | D24: RPE | E24: Isınma setleri | H24: Set 1 | I24: Set 2 | J24: Set 3 | K24: Set 4 | L24: Notlar
A25: ='Başlangıç'!$A$9 -> Over Head Press | B25: =IF('Hafta 2'!$K$25>=5,(('Hafta 2'!$B$25)+('Başlangıç'!$F$9)),MROUND(('Hafta 2'!$B$25*0.9),2.5)) -> 17.5 | C25: ='Başlangıç'!$H$9 -> 4x5+ | D25: ='Başlangıç'!$G$9 | E25: =MROUND((B25*0.6),2.5) -> 10 | F25: =MROUND((B25*0.7),2.5) -> 12.5 | G25: =MROUND((B25*0.85),2.5) -> 15
A26: ='Başlangıç'!$A$16 -> Squat | B26: =IF('Hafta 2'!$J$26=10,(('Hafta 2'!$B$26)+('Başlangıç'!$F$16)),MROUND(('Hafta 2'!$B$26*0.9),2.5)) -> 12.5 | C26: ='Başlangıç'!$H$16 -> 3x10 | D26: ='Başlangıç'!$G$16 | E26: =MROUND((B26*0.6),2.5) -> 7.5 | F26: =MROUND((B26*0.85),2.5) -> 10 | G26: -
A27: ='Başlangıç'!$A$15 -> Barbell Row | B27: =IF('Hafta 2'!$K$27=10,(('Hafta 2'!$B$27)+('Başlangıç'!$F$15)),MROUND(('Hafta 2'!$B$27*0.9),2.5)) -> 12.5 | C27: ='Başlangıç'!$H$15 -> 4x10 | D27: ='Başlangıç'!$G$15 | E27: =MROUND((B27*0.6),2.5) -> 7.5 | F27: =MROUND((B27*0.85),2.5) -> 10 | G27: -
A28: ='Başlangıç'!$A$22 -> Chest Fly Machine | B28: =IF('Hafta 2'!$H$28+'Hafta 2'!$I$28+'Hafta 2'!$J$28>=42,'Hafta 2'!$B$28+'Başlangıç'!$F$22,'Hafta 2'!$B$28) -> 27.5 | C28: ='Başlangıç'!$H$22 -> 3x10-14 | D28: ='Başlangıç'!$G$22 -> 8 | E28: - | F28: - | G28: -
A29: ='Başlangıç'!$A$26 -> Overhead Triceps Extension | B29: =IF('Hafta 2'!$H$29+'Hafta 2'!$I$29+'Hafta 2'!$J$29>=36,'Hafta 2'!$B$29+'Başlangıç'!$F$26,'Hafta 2'!$B$29) -> 15 | C29: ='Başlangıç'!$H$26 -> 3x8-12 | D29: ='Başlangıç'!$G$26 -> 9 | E29: - | F29: - | G29: -
A30: ='Başlangıç'!$A$30 -> Deadbug | B30: ='Başlangıç'!$E$30 -> vücut a. | C30: ='Başlangıç'!$H$30 -> 3xmax | D30: ='Başlangıç'!$G$30 -> 9 | E30: - | F30: - | G30: -

Sheet Sayfa4

Sheet Hafta 4
A1: Vücut ağırlığı 👉 | B1: ='Başlangıç'!$B$3 -> 78.8
A3: WORKOUT A | C3: 1 tekrar max tahmini 👉 | G3: =A5 -> Bench Press | I3: =MROUND((IF(J5="","",SUM((B5*(MAX(H5,I5,J5,K5))*0.0333)+B5))), 0.5) -> 0
A4: Egzersiz | B4: Kg | C4: Set x Tekrar | D4: RPE | E4: Isınma setleri | H4: Set 1 | I4: Set 2 | J4: Set 3 | K4: Set 4 | L4: Notlar
A5: ='Başlangıç'!$A$7 -> Bench Press | B5: =IF('Hafta 3'!$K$5>=5,(('Hafta 3'!$B$5)+('Başlangıç'!$F$7)),MROUND(('Hafta 3'!$B$5*0.9),2.5)) -> 12.5 | C5: ='Başlangıç'!$H$7 -> 4x5+ | D5: ='Başlangıç'!$G$7 | E5: =MROUND((B5*0.6),2.5) -> 7.5 | F5: =MROUND((B5*0.7),2.5) -> 10 | G5: =MROUND((B5*0.85),2.5) -> 10 | M5: 👈 bu alanı not tutmak için kullanabilirsin
A6: ='Başlangıç'!$A$12 -> DB Shoulder Press | B6: =IF('Hafta 3'!$J$6=10,(('Hafta 3'!$B$6)+('Başlangıç'!$F$12)),MROUND(('Hafta 3'!$B$6*0.9),2.5)) -> 7.5 | C6: ='Başlangıç'!$H$12 -> 3x10 | D6: ='Başlangıç'!$G$12 | E6: =MROUND((B6*0.6),2.5) -> 5 | F6: =MROUND((B6*0.85),2.5) -> 7.5 | G6: -
A7: ='Başlangıç'!$A$13 -> Dumbbell Romanian Deadlift | B7: =IF('Hafta 3'!$J$7=8,(('Hafta 3'!$B$7)+('Başlangıç'!$F$13)),MROUND(('Hafta 3'!$B$7*0.9),2.5)) -> 17.5 | C7: ='Başlangıç'!$H$13 -> 3x8 | D7: ='Başlangıç'!$G$13 | E7: =MROUND((B7*0.6),2.5) -> 10 | F7: =MROUND((B7*0.85),2.5) -> 15 | G7: -
A8: ='Başlangıç'!$A$21 -> Lat Pulldown | B8: =IF('Hafta 3'!$H$8+'Hafta 3'!$I$8+'Hafta 3'!$J$8>=42,'Hafta 3'!$B$8+'Başlangıç'!$F$21,'Hafta 3'!$B$8) -> 32.5 | C8: ='Başlangıç'!$H$21 -> 3x10-14 | D8: ='Başlangıç'!$G$21 -> 8 | E8: - | F8: - | G8: -
A9: ='Başlangıç'!$A$23 -> Dumbbell Lunges | B9: =IF('Hafta 3'!$H$9+'Hafta 3'!$I$9+'Hafta 3'!$J$9>=42,'Hafta 3'!$B$9+'Başlangıç'!$F$23,'Hafta 3'!$B$9) -> 10 | C9: ='Başlangıç'!$H$23 -> 3x10-14 | D9: ='Başlangıç'!$G$23 -> 9 | E9: - | F9: - | G9: -
A10: ='Başlangıç'!$A$28 -> Crunch | B10: ='Başlangıç'!$E$28 -> vücut a. | C10: ='Başlangıç'!$H$28 -> 3xmax | D10: ='Başlangıç'!$G$28 -> 9 | E10: - | F10: - | G10: -
H11: 👆 her set için yaptığın tekrar sayılarını gir
A13: WORKOUT B | C13: 1 tekrar max tahmini 👉 | G13: =A15 -> Squat | I13: =MROUND((IF(J15="","",SUM((B15*(MAX(H15,I15,J15,K15))*0.0333)+B15))), 0.5) -> 0
A14: Egzersiz | B14: Kg | C14: Set x Tekrar | D14: RPE | E14: Isınma setleri | H14: Set 1 | I14: Set 2 | J14: Set 3 | K14: Set 4 | L14: Notlar
A15: ='Başlangıç'!$A$8 -> Squat | B15: =IF('Hafta 3'!$K$15>=5,(('Hafta 3'!$B$15)+('Başlangıç'!$F$8)),MROUND(('Hafta 3'!$B$15*0.9),2.5)) -> 22.5 | C15: ='Başlangıç'!$H$8 -> 4x5+ | D15: ='Başlangıç'!$G$8 | E15: =MROUND((B15*0.6),2.5) -> 12.5 | F15: =MROUND((B15*0.7),2.5) -> 15 | G15: =MROUND((B15*0.85),2.5) -> 20
A16: ='Başlangıç'!$A$14 -> Bench Press | B16: =IF('Hafta 3'!$J$16=10,(('Hafta 3'!$B$16)+('Başlangıç'!$F$14)),MROUND(('Hafta 3'!$B$16*0.9),2.5)) -> 10 | C16: ='Başlangıç'!$H$14 -> 3x10 | D16: ='Başlangıç'!$G$14 | E16: =MROUND((B16*0.6),2.5) -> 5 | F16: =MROUND((B16*0.85),2.5) -> 7.5 | G16: -
A17: ='Başlangıç'!$A$17 -> Negative Pull Ups | B17: ='Başlangıç'!$E$17 -> vücut a. | C17: ='Başlangıç'!$H$17 -> 3xmax | D17: ='Başlangıç'!$G$17 -> 9 | E17: - | F17: - | G17: -
A18: ='Başlangıç'!$A$20 -> Lateral Raises | B18: =IF('Hafta 3'!$H$18+'Hafta 3'!$I$18+'Hafta 3'!$J$18>=42,'Hafta 3'!$B$18+'Başlangıç'!$F$20,'Hafta 3'!$B$18) -> 5 | C18: ='Başlangıç'!$H$20 -> 3x10-14 | D18: ='Başlangıç'!$G$20 -> 9 | E18: - | F18: - | G18: -
A19: ='Başlangıç'!$A$27 -> Incline Dumbbell Curl | B19: =IF('Hafta 3'!$H$19+'Hafta 3'!$I$19+'Hafta 3'!$J$19>=36,'Hafta 3'!$B$19+'Başlangıç'!$F$27,'Hafta 3'!$B$19) -> 5 | C19: ='Başlangıç'!$H$27 -> 3x8-12 | D19: ='Başlangıç'!$G$27 -> 9 | E19: - | F19: - | G19: -
A20: ='Başlangıç'!$A$29 -> Leg Raises | B20: ='Başlangıç'!$E$29 -> vücut a. | C20: ='Başlangıç'!$H$29 -> 3xmax | D20: ='Başlangıç'!$G$29 -> 9 | E20: - | F20: - | G20: -
A23: WORKOUT C | C23: 1 tekrar max tahmini 👉 | G23: =A25 -> Over Head Press | I23: =MROUND((IF(J25="","",SUM((B25*(MAX(H25,I25,J25,K25))*0.0333)+B25))), 0.5) -> 0
A24: Egzersiz | B24: Kg | C24: Set x Tekrar | D24: RPE | E24: Isınma setleri | H24: Set 1 | I24: Set 2 | J24: Set 3 | K24: Set 4 | L24: Notlar
A25: ='Başlangıç'!$A$9 -> Over Head Press | B25: =IF('Hafta 3'!$K$25>=5,(('Hafta 3'!$B$25)+('Başlangıç'!$F$9)),MROUND(('Hafta 3'!$B$25*0.9),2.5)) -> 15 | C25: ='Başlangıç'!$H$9 -> 4x5+ | D25: ='Başlangıç'!$G$9 | E25: =MROUND((B25*0.6),2.5) -> 10 | F25: =MROUND((B25*0.7),2.5) -> 10 | G25: =MROUND((B25*0.85),2.5) -> 12.5
A26: ='Başlangıç'!$A$16 -> Squat | B26: =IF('Hafta 3'!$J$26=10,(('Hafta 3'!$B$26)+('Başlangıç'!$F$16)),MROUND(('Hafta 3'!$B$26*0.9),2.5)) -> 12.5 | C26: ='Başlangıç'!$H$16 -> 3x10 | D26: ='Başlangıç'!$G$16 | E26: =MROUND((B26*0.6),2.5) -> 7.5 | F26: =MROUND((B26*0.85),2.5) -> 10 | G26: -
A27: ='Başlangıç'!$A$15 -> Barbell Row | B27: =IF('Hafta 3'!$K$27=10,(('Hafta 3'!$B$27)+('Başlangıç'!$F$15)),MROUND(('Hafta 3'!$B$27*0.9),2.5)) -> 12.5 | C27: ='Başlangıç'!$H$15 -> 4x10 | D27: ='Başlangıç'!$G$15 | E27: =MROUND((B27*0.6),2.5) -> 7.5 | F27: =MROUND((B27*0.85),2.5) -> 10 | G27: -
A28: ='Başlangıç'!$A$22 -> Chest Fly Machine | B28: =IF('Hafta 3'!$H$28+'Hafta 3'!$I$28+'Hafta 3'!$J$28>=42,'Hafta 3'!$B$28+'Başlangıç'!$F$22,'Hafta 3'!$B$28) -> 27.5 | C28: ='Başlangıç'!$H$22 -> 3x10-14 | D28: ='Başlangıç'!$G$22 -> 8 | E28: - | F28: - | G28: -
A29: ='Başlangıç'!$A$26 -> Overhead Triceps Extension | B29: =IF('Hafta 3'!$H$29+'Hafta 3'!$I$29+'Hafta 3'!$J$29>=36,'Hafta 3'!$B$29+'Başlangıç'!$F$26,'Hafta 3'!$B$29) -> 15 | C29: ='Başlangıç'!$H$26 -> 3x8-12 | D29: ='Başlangıç'!$G$26 -> 9 | E29: - | F29: - | G29: -
A30: ='Başlangıç'!$A$30 -> Deadbug | B30: ='Başlangıç'!$E$30 -> vücut a. | C30: ='Başlangıç'!$H$30 -> 3xmax | D30: ='Başlangıç'!$G$30 -> 9 | E30: - | F30: - | G30: -

Sheet Hafta 5
A1: Vücut ağırlığı 👉 | B1: ='Başlangıç'!$B$3 -> 78.8
A3: WORKOUT A | C3: 1 tekrar max tahmini 👉 | G3: =A5 -> Bench Press | I3: =MROUND((IF(J5="","",SUM((B5*(MAX(H5,I5,J5,K5))*0.0333)+B5))), 0.5) -> 0
A4: Egzersiz | B4: Kg | C4: Set x Tekrar | D4: RPE | E4: Isınma setleri | H4: Set 1 | I4: Set 2 | J4: Set 3 | K4: Set 4 | L4: Notlar
A5: ='Başlangıç'!$A$7 -> Bench Press | B5: =IF('Hafta 4'!$K$5>=5,(('Hafta 4'!$B$5)+('Başlangıç'!$F$7)),MROUND(('Hafta 4'!$B$5*0.9),2.5)) -> 12.5 | C5: ='Başlangıç'!$H$7 -> 4x5+ | D5: ='Başlangıç'!$G$7 | E5: =MROUND((B5*0.6),2.5) -> 7.5 | F5: =MROUND((B5*0.7),2.5) -> 10 | G5: =MROUND((B5*0.85),2.5) -> 10 | M5: 👈 bu alanı not tutmak için kullanabilirsin
A6: ='Başlangıç'!$A$12 -> DB Shoulder Press | B6: =IF('Hafta 4'!$J$6=10,(('Hafta 4'!$B$6)+('Başlangıç'!$F$12)),MROUND(('Hafta 4'!$B$6*0.9),2.5)) -> 7.5 | C6: ='Başlangıç'!$H$12 -> 3x10 | D6: ='Başlangıç'!$G$12 | E6: =MROUND((B6*0.6),2.5) -> 5 | F6: =MROUND((B6*0.85),2.5) -> 7.5 | G6: -
A7: ='Başlangıç'!$A$13 -> Dumbbell Romanian Deadlift | B7: =IF('Hafta 4'!$J$7=8,(('Hafta 4'!$B$7)+('Başlangıç'!$F$13)),MROUND(('Hafta 4'!$B$7*0.9),2.5)) -> 15 | C7: ='Başlangıç'!$H$13 -> 3x8 | D7: ='Başlangıç'!$G$13 | E7: =MROUND((B7*0.6),2.5) -> 10 | F7: =MROUND((B7*0.85),2.5) -> 12.5 | G7: -
A8: ='Başlangıç'!$A$21 -> Lat Pulldown | B8: =IF('Hafta 4'!$H$8+'Hafta 4'!$I$8+'Hafta 4'!$J$8>=42,'Hafta 4'!$B$8+'Başlangıç'!$F$21,'Hafta 4'!$B$8) -> 32.5 | C8: ='Başlangıç'!$H$21 -> 3x10-14 | D8: ='Başlangıç'!$G$21 -> 8 | E8: - | F8: - | G8: -
A9: ='Başlangıç'!$A$23 -> Dumbbell Lunges | B9: =IF('Hafta 4'!$H$9+'Hafta 4'!$I$9+'Hafta 4'!$J$9>=42,'Hafta 4'!$B$9+'Başlangıç'!$F$23,'Hafta 4'!$B$9) -> 10 | C9: ='Başlangıç'!$H$23 -> 3x10-14 | D9: ='Başlangıç'!$G$23 -> 9 | E9: - | F9: - | G9: -
A10: ='Başlangıç'!$A$28 -> Crunch | B10: ='Başlangıç'!$E$28 -> vücut a. | C10: ='Başlangıç'!$H$28 -> 3xmax | D10: ='Başlangıç'!$G$28 -> 9 | E10: - | F10: - | G10: -
H11: 👆 her set için yaptığın tekrar sayılarını gir
A13: WORKOUT B | C13: 1 tekrar max tahmini 👉 | G13: =A15 -> Squat | I13: =MROUND((IF(J15="","",SUM((B15*(MAX(H15,I15,J15,K15))*0.0333)+B15))), 0.5) -> 0
A14: Egzersiz | B14: Kg | C14: Set x Tekrar | D14: RPE | E14: Isınma setleri | H14: Set 1 | I14: Set 2 | J14: Set 3 | K14: Set 4 | L14: Notlar
A15: ='Başlangıç'!$A$8 -> Squat | B15: =IF('Hafta 4'!$K$15>=5,(('Hafta 4'!$B$15)+('Başlangıç'!$F$8)),MROUND(('Hafta 4'!$B$15*0.9),2.5)) -> 20 | C15: ='Başlangıç'!$H$8 -> 4x5+ | D15: ='Başlangıç'!$G$8 | E15: =MROUND((B15*0.6),2.5) -> 12.5 | F15: =MROUND((B15*0.7),2.5) -> 15 | G15: =MROUND((B15*0.85),2.5) -> 17.5
A16: ='Başlangıç'!$A$14 -> Bench Press | B16: =IF('Hafta 4'!$J$16=10,(('Hafta 4'!$B$16)+('Başlangıç'!$F$14)),MROUND(('Hafta 4'!$B$16*0.9),2.5)) -> 10 | C16: ='Başlangıç'!$H$14 -> 3x10 | D16: ='Başlangıç'!$G$14 | E16: =MROUND((B16*0.6),2.5) -> 5 | F16: =MROUND((B16*0.85),2.5) -> 7.5 | G16: -
A17: ='Başlangıç'!$A$17 -> Negative Pull Ups | B17: ='Başlangıç'!$E$17 -> vücut a. | C17: ='Başlangıç'!$H$17 -> 3xmax | D17: ='Başlangıç'!$G$17 -> 9 | E17: - | F17: - | G17: -
A18: ='Başlangıç'!$A$20 -> Lateral Raises | B18: =IF('Hafta 4'!$H$18+'Hafta 4'!$I$18+'Hafta 4'!$J$18>=42,'Hafta 4'!$B$18+'Başlangıç'!$F$20,'Hafta 4'!$B$18) -> 5 | C18: ='Başlangıç'!$H$20 -> 3x10-14 | D18: ='Başlangıç'!$G$20 -> 9 | E18: - | F18: - | G18: -
A19: ='Başlangıç'!$A$27 -> Incline Dumbbell Curl | B19: =IF('Hafta 4'!$H$19+'Hafta 4'!$I$19+'Hafta 4'!$J$19>=36,'Hafta 4'!$B$19+'Başlangıç'!$F$27,'Hafta 4'!$B$19) -> 5 | C19: ='Başlangıç'!$H$27 -> 3x8-12 | D19: ='Başlangıç'!$G$27 -> 9 | E19: - | F19: - | G19: -
A20: ='Başlangıç'!$A$29 -> Leg Raises | B20: ='Başlangıç'!$E$29 -> vücut a. | C20: ='Başlangıç'!$H$29 -> 3xmax | D20: ='Başlangıç'!$G$29 -> 9 | E20: - | F20: - | G20: -
A23: WORKOUT C | C23: 1 tekrar max tahmini 👉 | G23: =A25 -> Over Head Press | I23: =MROUND((IF(J25="","",SUM((B25*(MAX(H25,I25,J25,K25))*0.0333)+B25))), 0.5) -> 0
A24: Egzersiz | B24: Kg | C24: Set x Tekrar | D24: RPE | E24: Isınma setleri | H24: Set 1 | I24: Set 2 | J24: Set 3 | K24: Set 4 | L24: Notlar
A25: ='Başlangıç'!$A$9 -> Over Head Press | B25: =IF('Hafta 4'!$K$25>=5,(('Hafta 4'!$B$25)+('Başlangıç'!$F$9)),MROUND(('Hafta 4'!$B$25*0.9),2.5)) -> 12.5 | C25: ='Başlangıç'!$H$9 -> 4x5+ | D25: ='Başlangıç'!$G$9 | E25: =MROUND((B25*0.6),2.5) -> 7.5 | F25: =MROUND((B25*0.7),2.5) -> 10 | G25: =MROUND((B25*0.85),2.5) -> 10
A26: ='Başlangıç'!$A$16 -> Squat | B26: =IF('Hafta 4'!$J$26=10,(('Hafta 4'!$B$26)+('Başlangıç'!$F$16)),MROUND(('Hafta 4'!$B$26*0.9),2.5)) -> 12.5 | C26: ='Başlangıç'!$H$16 -> 3x10 | D26: ='Başlangıç'!$G$16 | E26: =MROUND((B26*0.6),2.5) -> 7.5 | F26: =MROUND((B26*0.85),2.5) -> 10 | G26: -
A27: ='Başlangıç'!$A$15 -> Barbell Row | B27: =IF('Hafta 4'!$K$27=10,(('Hafta 4'!$B$27)+('Başlangıç'!$F$15)),MROUND(('Hafta 4'!$B$27*0.9),2.5)) -> 12.5 | C27: ='Başlangıç'!$H$15 -> 4x10 | D27: ='Başlangıç'!$G$15 | E27: =MROUND((B27*0.6),2.5) -> 7.5 | F27: =MROUND((B27*0.85),2.5) -> 10 | G27: -
A28: ='Başlangıç'!$A$22 -> Chest Fly Machine | B28: =IF('Hafta 4'!$H$28+'Hafta 4'!$I$28+'Hafta 4'!$J$28>=42,'Hafta 4'!$B$28+'Başlangıç'!$F$22,'Hafta 4'!$B$28) -> 27.5 | C28: ='Başlangıç'!$H$22 -> 3x10-14 | D28: ='Başlangıç'!$G$22 -> 8 | E28: - | F28: - | G28: -
A29: ='Başlangıç'!$A$26 -> Overhead Triceps Extension | B29: =IF('Hafta 4'!$H$29+'Hafta 4'!$I$29+'Hafta 4'!$J$29>=36,'Hafta 4'!$B$29+'Başlangıç'!$F$26,'Hafta 4'!$B$29) -> 15 | C29: ='Başlangıç'!$H$26 -> 3x8-12 | D29: ='Başlangıç'!$G$26 -> 9 | E29: - | F29: - | G29: -
A30: ='Başlangıç'!$A$30 -> Deadbug | B30: ='Başlangıç'!$E$30 -> vücut a. | C30: ='Başlangıç'!$H$30 -> 3xmax | D30: ='Başlangıç'!$G$30 -> 9 | E30: - | F30: - | G30: -

Sheet Hafta 6
A1: Vücut ağırlığı 👉 | B1: ='Başlangıç'!$B$3 -> 78.8
A3: WORKOUT A | C3: 1 tekrar max tahmini 👉 | G3: =A5 -> Bench Press | I3: =MROUND((IF(J5="","",SUM((B5*(MAX(H5,I5,J5,K5))*0.0333)+B5))), 0.5) -> 0
A4: Egzersiz | B4: Kg | C4: Set x Tekrar | D4: RPE | E4: Isınma setleri | H4: Set 1 | I4: Set 2 | J4: Set 3 | K4: Set 4 | L4: Notlar
A5: ='Başlangıç'!$A$7 -> Bench Press | B5: =IF('Hafta 5'!$K$5>=5,(('Hafta 5'!$B$5)+('Başlangıç'!$F$7)),MROUND(('Hafta 5'!$B$5*0.9),2.5)) -> 12.5 | C5: ='Başlangıç'!$H$7 -> 4x5+ | D5: ='Başlangıç'!$G$7 | E5: =MROUND((B5*0.6),2.5) -> 7.5 | F5: =MROUND((B5*0.7),2.5) -> 10 | G5: =MROUND((B5*0.85),2.5) -> 10 | M5: 👈 bu alanı not tutmak için kullanabilirsin
A6: ='Başlangıç'!$A$12 -> DB Shoulder Press | B6: =IF('Hafta 5'!$J$6=10,(('Hafta 5'!$B$6)+('Başlangıç'!$F$12)),MROUND(('Hafta 5'!$B$6*0.9),2.5)) -> 7.5 | C6: ='Başlangıç'!$H$12 -> 3x10 | D6: ='Başlangıç'!$G$12 | E6: =MROUND((B6*0.6),2.5) -> 5 | F6: =MROUND((B6*0.85),2.5) -> 7.5 | G6: -
A7: ='Başlangıç'!$A$13 -> Dumbbell Romanian Deadlift | B7: =IF('Hafta 5'!$J$7=8,(('Hafta 5'!$B$7)+('Başlangıç'!$F$13)),MROUND(('Hafta 5'!$B$7*0.9),2.5)) -> 12.5 | C7: ='Başlangıç'!$H$13 -> 3x8 | D7: ='Başlangıç'!$G$13 | E7: =MROUND((B7*0.6),2.5) -> 7.5 | F7: =MROUND((B7*0.85),2.5) -> 10 | G7: -
A8: ='Başlangıç'!$A$21 -> Lat Pulldown | B8: =IF('Hafta 5'!$H$8+'Hafta 5'!$I$8+'Hafta 5'!$J$8>=42,'Hafta 5'!$B$8+'Başlangıç'!$F$21,'Hafta 5'!$B$8) -> 32.5 | C8: ='Başlangıç'!$H$21 -> 3x10-14 | D8: ='Başlangıç'!$G$21 -> 8 | E8: - | F8: - | G8: -
A9: ='Başlangıç'!$A$23 -> Dumbbell Lunges | B9: =IF('Hafta 5'!$H$9+'Hafta 5'!$I$9+'Hafta 5'!$J$9>=42,'Hafta 5'!$B$9+'Başlangıç'!$F$23,'Hafta 5'!$B$9) -> 10 | C9: ='Başlangıç'!$H$23 -> 3x10-14 | D9: ='Başlangıç'!$G$23 -> 9 | E9: - | F9: - | G9: -
A10: ='Başlangıç'!$A$28 -> Crunch | B10: ='Başlangıç'!$E$28 -> vücut a. | C10: ='Başlangıç'!$H$28 -> 3xmax | D10: ='Başlangıç'!$G$28 -> 9 | E10: - | F10: - | G10: -
H11: 👆 her set için yaptığın tekrar sayılarını gir
A13: WORKOUT B | C13: 1 tekrar max tahmini 👉 | G13: =A15 -> Squat | I13: =MROUND((IF(J15="","",SUM((B15*(MAX(H15,I15,J15,K15))*0.0333)+B15))), 0.5) -> 0
A14: Egzersiz | B14: Kg | C14: Set x Tekrar | D14: RPE | E14: Isınma setleri | H14: Set 1 | I14: Set 2 | J14: Set 3 | K14: Set 4 | L14: Notlar
A15: ='Başlangıç'!$A$8 -> Squat | B15: =IF('Hafta 5'!$K$15>=5,(('Hafta 5'!$B$15)+('Başlangıç'!$F$8)),MROUND(('Hafta 5'!$B$15*0.9),2.5)) -> 17.5 | C15: ='Başlangıç'!$H$8 -> 4x5+ | D15: ='Başlangıç'!$G$8 | E15: =MROUND((B15*0.6),2.5) -> 10 | F15: =MROUND((B15*0.7),2.5) -> 12.5 | G15: =MROUND((B15*0.85),2.5) -> 15
A16: ='Başlangıç'!$A$14 -> Bench Press | B16: =IF('Hafta 5'!$J$16=10,(('Hafta 5'!$B$16)+('Başlangıç'!$F$14)),MROUND(('Hafta 5'!$B$16*0.9),2.5)) -> 10 | C16: ='Başlangıç'!$H$14 -> 3x10 | D16: ='Başlangıç'!$G$14 | E16: =MROUND((B16*0.6),2.5) -> 5 | F16: =MROUND((B16*0.85),2.5) -> 7.5 | G16: -
A17: ='Başlangıç'!$A$17 -> Negative Pull Ups | B17: ='Başlangıç'!$E$17 -> vücut a. | C17: ='Başlangıç'!$H$17 -> 3xmax | D17: ='Başlangıç'!$G$17 -> 9 | E17: - | F17: - | G17: -
A18: ='Başlangıç'!$A$20 -> Lateral Raises | B18: =IF('Hafta 5'!$H$18+'Hafta 5'!$I$18+'Hafta 5'!$J$18>=42,'Hafta 5'!$B$18+'Başlangıç'!$F$20,'Hafta 5'!$B$18) -> 5 | C18: ='Başlangıç'!$H$20 -> 3x10-14 | D18: ='Başlangıç'!$G$20 -> 9 | E18: - | F18: - | G18: -
A19: ='Başlangıç'!$A$27 -> Incline Dumbbell Curl | B19: =IF('Hafta 5'!$H$19+'Hafta 5'!$I$19+'Hafta 5'!$J$19>=36,'Hafta 5'!$B$19+'Başlangıç'!$F$27,'Hafta 5'!$B$19) -> 5 | C19: ='Başlangıç'!$H$27 -> 3x8-12 | D19: ='Başlangıç'!$G$27 -> 9 | E19: - | F19: - | G19: -
A20: ='Başlangıç'!$A$29 -> Leg Raises | B20: ='Başlangıç'!$E$29 -> vücut a. | C20: ='Başlangıç'!$H$29 -> 3xmax | D20: ='Başlangıç'!$G$29 -> 9 | E20: - | F20: - | G20: -
A23: WORKOUT C | C23: 1 tekrar max tahmini 👉 | G23: =A25 -> Over Head Press | I23: =MROUND((IF(J25="","",SUM((B25*(MAX(H25,I25,J25,K25))*0.0333)+B25))), 0.5) -> 0
A24: Egzersiz | B24: Kg | C24: Set x Tekrar | D24: RPE | E24: Isınma setleri | H24: Set 1 | I24: Set 2 | J24: Set 3 | K24: Set 4 | L24: Notlar
A25: ='Başlangıç'!$A$9 -> Over Head Press | B25: =IF('Hafta 5'!$K$25>=5,(('Hafta 5'!$B$25)+('Başlangıç'!$F$9)),MROUND(('Hafta 5'!$B$25*0.9),2.5)) -> 12.5 | C25: ='Başlangıç'!$H$9 -> 4x5+ | D25: ='Başlangıç'!$G$9 | E25: =MROUND((B25*0.6),2.5) -> 7.5 | F25: =MROUND((B25*0.7),2.5) -> 10 | G25: =MROUND((B25*0.85),2.5) -> 10
A26: ='Başlangıç'!$A$16 -> Squat | B26: =IF('Hafta 5'!$J$26=10,(('Hafta 5'!$B$26)+('Başlangıç'!$F$16)),MROUND(('Hafta 5'!$B$26*0.9),2.5)) -> 12.5 | C26: ='Başlangıç'!$H$16 -> 3x10 | D26: ='Başlangıç'!$G$16 | E26: =MROUND((B26*0.6),2.5) -> 7.5 | F26: =MROUND((B26*0.85),2.5) -> 10 | G26: -
A27: ='Başlangıç'!$A$15 -> Barbell Row | B27: =IF('Hafta 5'!$K$27=10,(('Hafta 5'!$B$27)+('Başlangıç'!$F$15)),MROUND(('Hafta 5'!$B$27*0.9),2.5)) -> 12.5 | C27: ='Başlangıç'!$H$15 -> 4x10 | D27: ='Başlangıç'!$G$15 | E27: =MROUND((B27*0.6),2.5) -> 7.5 | F27: =MROUND((B27*0.85),2.5) -> 10 | G27: -
A28: ='Başlangıç'!$A$22 -> Chest Fly Machine | B28: =IF('Hafta 5'!$H$28+'Hafta 5'!$I$28+'Hafta 5'!$J$28>=42,'Hafta 5'!$B$28+'Başlangıç'!$F$22,'Hafta 5'!$B$28) -> 27.5 | C28: ='Başlangıç'!$H$22 -> 3x10-14 | D28: ='Başlangıç'!$G$22 -> 8 | E28: - | F28: - | G28: -
A29: ='Başlangıç'!$A$26 -> Overhead Triceps Extension | B29: =IF('Hafta 5'!$H$29+'Hafta 5'!$I$29+'Hafta 5'!$J$29>=36,'Hafta 5'!$B$29+'Başlangıç'!$F$26,'Hafta 5'!$B$29) -> 15 | C29: ='Başlangıç'!$H$26 -> 3x8-12 | D29: ='Başlangıç'!$G$26 -> 9 | E29: - | F29: - | G29: -
A30: ='Başlangıç'!$A$30 -> Deadbug | B30: ='Başlangıç'!$E$30 -> vücut a. | C30: ='Başlangıç'!$H$30 -> 3xmax | D30: ='Başlangıç'!$G$30 -> 9 | E30: - | F30: - | G30: -

Sheet Hafta 7
A1: Vücut ağırlığı 👉 | B1: ='Başlangıç'!$B$3 -> 78.8
A3: WORKOUT A | C3: 1 tekrar max tahmini 👉 | G3: =A5 -> Bench Press | I3: =MROUND((IF(J5="","",SUM((B5*(MAX(H5,I5,J5,K5))*0.0333)+B5))), 0.5) -> 0
A4: Egzersiz | B4: Kg | C4: Set x Tekrar | D4: RPE | E4: Isınma setleri | H4: Set 1 | I4: Set 2 | J4: Set 3 | K4: Set 4 | L4: Notlar
A5: ='Başlangıç'!$A$7 -> Bench Press | B5: =IF('Hafta 6'!$K$5>=5,(('Hafta 6'!$B$5)+('Başlangıç'!$F$7)),MROUND(('Hafta 6'!$B$5*0.9),2.5)) -> 12.5 | C5: ='Başlangıç'!$H$7 -> 4x5+ | D5: ='Başlangıç'!$G$7 | E5: =MROUND((B5*0.6),2.5) -> 7.5 | F5: =MROUND((B5*0.7),2.5) -> 10 | G5: =MROUND((B5*0.85),2.5) -> 10 | M5: 👈 bu alanı not tutmak için kullanabilirsin
A6: ='Başlangıç'!$A$12 -> DB Shoulder Press | B6: =IF('Hafta 6'!$J$6=10,(('Hafta 6'!$B$6)+('Başlangıç'!$F$12)),MROUND(('Hafta 6'!$B$6*0.9),2.5)) -> 7.5 | C6: ='Başlangıç'!$H$12 -> 3x10 | D6: ='Başlangıç'!$G$12 | E6: =MROUND((B6*0.6),2.5) -> 5 | F6: =MROUND((B6*0.85),2.5) -> 7.5 | G6: -
A7: ='Başlangıç'!$A$13 -> Dumbbell Romanian Deadlift | B7: =IF('Hafta 6'!$J$7=8,(('Hafta 6'!$B$7)+('Başlangıç'!$F$13)),MROUND(('Hafta 6'!$B$7*0.9),2.5)) -> 12.5 | C7: ='Başlangıç'!$H$13 -> 3x8 | D7: ='Başlangıç'!$G$13 | E7: =MROUND((B7*0.6),2.5) -> 7.5 | F7: =MROUND((B7*0.85),2.5) -> 10 | G7: -
A8: ='Başlangıç'!$A$21 -> Lat Pulldown | B8: =IF('Hafta 6'!$H$8+'Hafta 6'!$I$8+'Hafta 6'!$J$8>=42,'Hafta 6'!$B$8+'Başlangıç'!$F$21,'Hafta 6'!$B$8) -> 32.5 | C8: ='Başlangıç'!$H$21 -> 3x10-14 | D8: ='Başlangıç'!$G$21 -> 8 | E8: - | F8: - | G8: -
A9: ='Başlangıç'!$A$23 -> Dumbbell Lunges | B9: =IF('Hafta 6'!$H$9+'Hafta 6'!$I$9+'Hafta 6'!$J$9>=42,'Hafta 6'!$B$9+'Başlangıç'!$F$23,'Hafta 6'!$B$9) -> 10 | C9: ='Başlangıç'!$H$23 -> 3x10-14 | D9: ='Başlangıç'!$G$23 -> 9 | E9: - | F9: - | G9: -
A10: ='Başlangıç'!$A$28 -> Crunch | B10: ='Başlangıç'!$E$28 -> vücut a. | C10: ='Başlangıç'!$H$28 -> 3xmax | D10: ='Başlangıç'!$G$28 -> 9 | E10: - | F10: - | G10: -
H11: 👆 her set için yaptığın tekrar sayılarını gir
A13: WORKOUT B | C13: 1 tekrar max tahmini 👉 | G13: =A15 -> Squat | I13: =MROUND((IF(J15="","",SUM((B15*(MAX(H15,I15,J15,K15))*0.0333)+B15))), 0.5) -> 0
A14: Egzersiz | B14: Kg | C14: Set x Tekrar | D14: RPE | E14: Isınma setleri | H14: Set 1 | I14: Set 2 | J14: Set 3 | K14: Set 4 | L14: Notlar
A15: ='Başlangıç'!$A$8 -> Squat | B15: =IF('Hafta 6'!$K$15>=5,(('Hafta 6'!$B$15)+('Başlangıç'!$F$8)),MROUND(('Hafta 6'!$B$15*0.9),2.5)) -> 15 | C15: ='Başlangıç'!$H$8 -> 4x5+ | D15: ='Başlangıç'!$G$8 | E15: =MROUND((B15*0.6),2.5) -> 10 | F15: =MROUND((B15*0.7),2.5) -> 10 | G15: =MROUND((B15*0.85),2.5) -> 12.5
A16: ='Başlangıç'!$A$14 -> Bench Press | B16: =IF('Hafta 6'!$J$16=10,(('Hafta 6'!$B$16)+('Başlangıç'!$F$14)),MROUND(('Hafta 6'!$B$16*0.9),2.5)) -> 10 | C16: ='Başlangıç'!$H$14 -> 3x10 | D16: ='Başlangıç'!$G$14 | E16: =MROUND((B16*0.6),2.5) -> 5 | F16: =MROUND((B16*0.85),2.5) -> 7.5 | G16: -
A17: ='Başlangıç'!$A$17 -> Negative Pull Ups | B17: ='Başlangıç'!$E$17 -> vücut a. | C17: ='Başlangıç'!$H$17 -> 3xmax | D17: ='Başlangıç'!$G$17 -> 9 | E17: - | F17: - | G17: -
A18: ='Başlangıç'!$A$20 -> Lateral Raises | B18: =IF('Hafta 6'!$H$18+'Hafta 6'!$I$18+'Hafta 6'!$J$18>=42,'Hafta 6'!$B$18+'Başlangıç'!$F$20,'Hafta 6'!$B$18) -> 5 | C18: ='Başlangıç'!$H$20 -> 3x10-14 | D18: ='Başlangıç'!$G$20 -> 9 | E18: - | F18: - | G18: -
A19: ='Başlangıç'!$A$27 -> Incline Dumbbell Curl | B19: =IF('Hafta 6'!$H$19+'Hafta 6'!$I$19+'Hafta 6'!$J$19>=36,'Hafta 6'!$B$19+'Başlangıç'!$F$27,'Hafta 6'!$B$19) -> 5 | C19: ='Başlangıç'!$H$27 -> 3x8-12 | D19: ='Başlangıç'!$G$27 -> 9 | E19: - | F19: - | G19: -
A20: ='Başlangıç'!$A$29 -> Leg Raises | B20: ='Başlangıç'!$E$29 -> vücut a. | C20: ='Başlangıç'!$H$29 -> 3xmax | D20: ='Başlangıç'!$G$29 -> 9 | E20: - | F20: - | G20: -
A23: WORKOUT C | C23: 1 tekrar max tahmini 👉 | G23: =A25 -> Over Head Press | I23: =MROUND((IF(J25="","",SUM((B25*(MAX(H25,I25,J25,K25))*0.0333)+B25))), 0.5) -> 0
A24: Egzersiz | B24: Kg | C24: Set x Tekrar | D24: RPE | E24: Isınma setleri | H24: Set 1 | I24: Set 2 | J24: Set 3 | K24: Set 4 | L24: Notlar
A25: ='Başlangıç'!$A$9 -> Over Head Press | B25: =IF('Hafta 6'!$K$25>=5,(('Hafta 6'!$B$25)+('Başlangıç'!$F$9)),MROUND(('Hafta 6'!$B$25*0.9),2.5)) -> 12.5 | C25: ='Başlangıç'!$H$9 -> 4x5+ | D25: ='Başlangıç'!$G$9 | E25: =MROUND((B25*0.6),2.5) -> 7.5 | F25: =MROUND((B25*0.7),2.5) -> 10 | G25: =MROUND((B25*0.85),2.5) -> 10
A26: ='Başlangıç'!$A$16 -> Squat | B26: =IF('Hafta 6'!$J$26=10,(('Hafta 6'!$B$26)+('Başlangıç'!$F$16)),MROUND(('Hafta 6'!$B$26*0.9),2.5)) -> 12.5 | C26: ='Başlangıç'!$H$16 -> 3x10 | D26: ='Başlangıç'!$G$16 | E26: =MROUND((B26*0.6),2.5) -> 7.5 | F26: =MROUND((B26*0.85),2.5) -> 10 | G26: -
A27: ='Başlangıç'!$A$15 -> Barbell Row | B27: =IF('Hafta 6'!$K$27=10,(('Hafta 6'!$B$27)+('Başlangıç'!$F$15)),MROUND(('Hafta 6'!$B$27*0.9),2.5)) -> 12.5 | C27: ='Başlangıç'!$H$15 -> 4x10 | D27: ='Başlangıç'!$G$15 | E27: =MROUND((B27*0.6),2.5) -> 7.5 | F27: =MROUND((B27*0.85),2.5) -> 10 | G27: -
A28: ='Başlangıç'!$A$22 -> Chest Fly Machine | B28: =IF('Hafta 6'!$H$28+'Hafta 6'!$I$28+'Hafta 6'!$J$28>=42,'Hafta 6'!$B$28+'Başlangıç'!$F$22,'Hafta 6'!$B$28) -> 27.5 | C28: ='Başlangıç'!$H$22 -> 3x10-14 | D28: ='Başlangıç'!$G$22 -> 8 | E28: - | F28: - | G28: -
A29: ='Başlangıç'!$A$26 -> Overhead Triceps Extension | B29: =IF('Hafta 6'!$H$29+'Hafta 6'!$I$29+'Hafta 6'!$J$29>=36,'Hafta 6'!$B$29+'Başlangıç'!$F$26,'Hafta 6'!$B$29) -> 15 | C29: ='Başlangıç'!$H$26 -> 3x8-12 | D29: ='Başlangıç'!$G$26 -> 9 | E29: - | F29: - | G29: -
A30: ='Başlangıç'!$A$30 -> Deadbug | B30: ='Başlangıç'!$E$30 -> vücut a. | C30: ='Başlangıç'!$H$30 -> 3xmax | D30: ='Başlangıç'!$G$30 -> 9 | E30: - | F30: - | G30: -

Sheet Hafta 8
A1: Vücut ağırlığı 👉 | B1: ='Başlangıç'!$B$3 -> 78.8
A3: WORKOUT A | C3: 1 tekrar max tahmini 👉 | G3: =A5 -> Bench Press | I3: =MROUND((IF(J5="","",SUM((B5*(MAX(H5,I5,J5,K5))*0.0333)+B5))), 0.5) -> 0
A4: Egzersiz | B4: Kg | C4: Set x Tekrar | D4: RPE | E4: Isınma setleri | H4: Set 1 | I4: Set 2 | J4: Set 3 | K4: Set 4 | L4: Notlar
A5: ='Başlangıç'!$A$7 -> Bench Press | B5: =IF('Hafta 7'!$K$5>=5,(('Hafta 7'!$B$5)+('Başlangıç'!$F$7)),MROUND(('Hafta 7'!$B$5*0.9),2.5)) -> 12.5 | C5: ='Başlangıç'!$H$7 -> 4x5+ | D5: ='Başlangıç'!$G$7 | E5: =MROUND((B5*0.6),2.5) -> 7.5 | F5: =MROUND((B5*0.7),2.5) -> 10 | G5: =MROUND((B5*0.85),2.5) -> 10 | M5: 👈 bu alanı not tutmak için kullanabilirsin
A6: ='Başlangıç'!$A$12 -> DB Shoulder Press | B6: =IF('Hafta 7'!$J$6=10,(('Hafta 7'!$B$6)+('Başlangıç'!$F$12)),MROUND(('Hafta 7'!$B$6*0.9),2.5)) -> 7.5 | C6: ='Başlangıç'!$H$12 -> 3x10 | D6: ='Başlangıç'!$G$12 | E6: =MROUND((B6*0.6),2.5) -> 5 | F6: =MROUND((B6*0.85),2.5) -> 7.5 | G6: -
A7: ='Başlangıç'!$A$13 -> Dumbbell Romanian Deadlift | B7: =IF('Hafta 7'!$J$7=8,(('Hafta 7'!$B$7)+('Başlangıç'!$F$13)),MROUND(('Hafta 7'!$B$7*0.9),2.5)) -> 12.5 | C7: ='Başlangıç'!$H$13 -> 3x8 | D7: ='Başlangıç'!$G$13 | E7: =MROUND((B7*0.6),2.5) -> 7.5 | F7: =MROUND((B7*0.85),2.5) -> 10 | G7: -
A8: ='Başlangıç'!$A$21 -> Lat Pulldown | B8: =IF('Hafta 7'!$H$8+'Hafta 7'!$I$8+'Hafta 7'!$J$8>=42,'Hafta 7'!$B$8+'Başlangıç'!$F$21,'Hafta 7'!$B$8) -> 32.5 | C8: ='Başlangıç'!$H$21 -> 3x10-14 | D8: ='Başlangıç'!$G$21 -> 8 | E8: - | F8: - | G8: -
A9: ='Başlangıç'!$A$23 -> Dumbbell Lunges | B9: =IF('Hafta 7'!$H$9+'Hafta 7'!$I$9+'Hafta 7'!$J$9>=42,'Hafta 7'!$B$9+'Başlangıç'!$F$23,'Hafta 7'!$B$9) -> 10 | C9: ='Başlangıç'!$H$23 -> 3x10-14 | D9: ='Başlangıç'!$G$23 -> 9 | E9: - | F9: - | G9: -
A10: ='Başlangıç'!$A$28 -> Crunch | B10: ='Başlangıç'!$E$28 -> vücut a. | C10: ='Başlangıç'!$H$28 -> 3xmax | D10: ='Başlangıç'!$G$28 -> 9 | E10: - | F10: - | G10: -
H11: 👆 her set için yaptığın tekrar sayılarını gir
A13: WORKOUT B | C13: 1 tekrar max tahmini 👉 | G13: =A15 -> Squat | I13: =MROUND((IF(J15="","",SUM((B15*(MAX(H15,I15,J15,K15))*0.0333)+B15))), 0.5) -> 0
A14: Egzersiz | B14: Kg | C14: Set x Tekrar | D14: RPE | E14: Isınma setleri | H14: Set 1 | I14: Set 2 | J14: Set 3 | K14: Set 4 | L14: Notlar
A15: ='Başlangıç'!$A$8 -> Squat | B15: =IF('Hafta 7'!$K$15>=5,(('Hafta 7'!$B$15)+('Başlangıç'!$F$8)),MROUND(('Hafta 7'!$B$15*0.9),2.5)) -> 12.5 | C15: ='Başlangıç'!$H$8 -> 4x5+ | D15: ='Başlangıç'!$G$8 | E15: =MROUND((B15*0.6),2.5) -> 7.5 | F15: =MROUND((B15*0.7),2.5) -> 10 | G15: =MROUND((B15*0.85),2.5) -> 10
A16: ='Başlangıç'!$A$14 -> Bench Press | B16: =IF('Hafta 7'!$J$16=10,(('Hafta 7'!$B$16)+('Başlangıç'!$F$14)),MROUND(('Hafta 7'!$B$16*0.9),2.5)) -> 10 | C16: ='Başlangıç'!$H$14 -> 3x10 | D16: ='Başlangıç'!$G$14 | E16: =MROUND((B16*0.6),2.5) -> 5 | F16: =MROUND((B16*0.85),2.5) -> 7.5 | G16: -
A17: ='Başlangıç'!$A$17 -> Negative Pull Ups | B17: ='Başlangıç'!$E$17 -> vücut a. | C17: ='Başlangıç'!$H$17 -> 3xmax | D17: ='Başlangıç'!$G$17 -> 9 | E17: - | F17: - | G17: -
A18: ='Başlangıç'!$A$20 -> Lateral Raises | B18: =IF('Hafta 7'!$H$18+'Hafta 7'!$I$18+'Hafta 7'!$J$18>=42,'Hafta 7'!$B$18+'Başlangıç'!$F$20,'Hafta 7'!$B$18) -> 5 | C18: ='Başlangıç'!$H$20 -> 3x10-14 | D18: ='Başlangıç'!$G$20 -> 9 | E18: - | F18: - | G18: -
A19: ='Başlangıç'!$A$27 -> Incline Dumbbell Curl | B19: =IF('Hafta 7'!$H$19+'Hafta 7'!$I$19+'Hafta 7'!$J$19>=36,'Hafta 7'!$B$19+'Başlangıç'!$F$27,'Hafta 7'!$B$19) -> 5 | C19: ='Başlangıç'!$H$27 -> 3x8-12 | D19: ='Başlangıç'!$G$27 -> 9 | E19: - | F19: - | G19: -
A20: ='Başlangıç'!$A$29 -> Leg Raises | B20: ='Başlangıç'!$E$29 -> vücut a. | C20: ='Başlangıç'!$H$29 -> 3xmax | D20: ='Başlangıç'!$G$29 -> 9 | E20: - | F20: - | G20: -
A23: WORKOUT C | C23: 1 tekrar max tahmini 👉 | G23: =A25 -> Over Head Press | I23: =MROUND((IF(J25="","",SUM((B25*(MAX(H25,I25,J25,K25))*0.0333)+B25))), 0.5) -> 0
A24: Egzersiz | B24: Kg | C24: Set x Tekrar | D24: RPE | E24: Isınma setleri | H24: Set 1 | I24: Set 2 | J24: Set 3 | K24: Set 4 | L24: Notlar
A25: ='Başlangıç'!$A$9 -> Over Head Press | B25: =IF('Hafta 7'!$K$25>=5,(('Hafta 7'!$B$25)+('Başlangıç'!$F$9)),MROUND(('Hafta 7'!$B$25*0.9),2.5)) -> 12.5 | C25: ='Başlangıç'!$H$9 -> 4x5+ | D25: ='Başlangıç'!$G$9 | E25: =MROUND((B25*0.6),2.5) -> 7.5 | F25: =MROUND((B25*0.7),2.5) -> 10 | G25: =MROUND((B25*0.85),2.5) -> 10
A26: ='Başlangıç'!$A$16 -> Squat | B26: =IF('Hafta 7'!$J$26=10,(('Hafta 7'!$B$26)+('Başlangıç'!$F$16)),MROUND(('Hafta 7'!$B$26*0.9),2.5)) -> 12.5 | C26: ='Başlangıç'!$H$16 -> 3x10 | D26: ='Başlangıç'!$G$16 | E26: =MROUND((B26*0.6),2.5) -> 7.5 | F26: =MROUND((B26*0.85),2.5) -> 10 | G26: -
A27: ='Başlangıç'!$A$15 -> Barbell Row | B27: =IF('Hafta 7'!$K$27=10,(('Hafta 7'!$B$27)+('Başlangıç'!$F$15)),MROUND(('Hafta 7'!$B$27*0.9),2.5)) -> 12.5 | C27: ='Başlangıç'!$H$15 -> 4x10 | D27: ='Başlangıç'!$G$15 | E27: =MROUND((B27*0.6),2.5) -> 7.5 | F27: =MROUND((B27*0.85),2.5) -> 10 | G27: -
A28: ='Başlangıç'!$A$22 -> Chest Fly Machine | B28: =IF('Hafta 7'!$H$28+'Hafta 7'!$I$28+'Hafta 7'!$J$28>=42,'Hafta 7'!$B$28+'Başlangıç'!$F$22,'Hafta 7'!$B$28) -> 27.5 | C28: ='Başlangıç'!$H$22 -> 3x10-14 | D28: ='Başlangıç'!$G$22 -> 8 | E28: - | F28: - | G28: -
A29: ='Başlangıç'!$A$26 -> Overhead Triceps Extension | B29: =IF('Hafta 7'!$H$29+'Hafta 7'!$I$29+'Hafta 7'!$J$29>=36,'Hafta 7'!$B$29+'Başlangıç'!$F$26,'Hafta 7'!$B$29) -> 15 | C29: ='Başlangıç'!$H$26 -> 3x8-12 | D29: ='Başlangıç'!$G$26 -> 9 | E29: - | F29: - | G29: -
A30: ='Başlangıç'!$A$30 -> Deadbug | B30: ='Başlangıç'!$E$30 -> vücut a. | C30: ='Başlangıç'!$H$30 -> 3xmax | D30: ='Başlangıç'!$G$30 -> 9 | E30: - | F30: - | G30: -

Sheet Hafta 9
A1: Vücut ağırlığı 👉 | B1: ='Başlangıç'!$B$3 -> 78.8
A3: WORKOUT A | C3: 1 tekrar max tahmini 👉 | G3: =A5 -> Bench Press | I3: =MROUND((IF(J5="","",SUM((B5*(MAX(H5,I5,J5,K5))*0.0333)+B5))), 0.5) -> 0
A4: Egzersiz | B4: Kg | C4: Set x Tekrar | D4: RPE | E4: Isınma setleri | H4: Set 1 | I4: Set 2 | J4: Set 3 | K4: Set 4 | L4: Notlar
A5: ='Başlangıç'!$A$7 -> Bench Press | B5: =IF('Hafta 8'!$K$5>=5,(('Hafta 8'!$B$5)+('Başlangıç'!$F$7)),MROUND(('Hafta 8'!$B$5*0.9),2.5)) -> 12.5 | C5: ='Başlangıç'!$H$7 -> 4x5+ | D5: ='Başlangıç'!$G$7 | E5: =MROUND((B5*0.6),2.5) -> 7.5 | F5: =MROUND((B5*0.7),2.5) -> 10 | G5: =MROUND((B5*0.85),2.5) -> 10 | M5: 👈 bu alanı not tutmak için kullanabilirsin
A6: ='Başlangıç'!$A$12 -> DB Shoulder Press | B6: =IF('Hafta 8'!$J$6=10,(('Hafta 8'!$B$6)+('Başlangıç'!$F$12)),MROUND(('Hafta 8'!$B$6*0.9),2.5)) -> 7.5 | C6: ='Başlangıç'!$H$12 -> 3x10 | D6: ='Başlangıç'!$G$12 | E6: =MROUND((B6*0.6),2.5) -> 5 | F6: =MROUND((B6*0.85),2.5) -> 7.5 | G6: -
A7: ='Başlangıç'!$A$13 -> Dumbbell Romanian Deadlift | B7: =IF('Hafta 8'!$J$7=8,(('Hafta 8'!$B$7)+('Başlangıç'!$F$13)),MROUND(('Hafta 8'!$B$7*0.9),2.5)) -> 12.5 | C7: ='Başlangıç'!$H$13 -> 3x8 | D7: ='Başlangıç'!$G$13 | E7: =MROUND((B7*0.6),2.5) -> 7.5 | F7: =MROUND((B7*0.85),2.5) -> 10 | G7: -
A8: ='Başlangıç'!$A$21 -> Lat Pulldown | B8: =IF('Hafta 8'!$H$8+'Hafta 8'!$I$8+'Hafta 8'!$J$8>=42,'Hafta 8'!$B$8+'Başlangıç'!$F$21,'Hafta 8'!$B$8) -> 32.5 | C8: ='Başlangıç'!$H$21 -> 3x10-14 | D8: ='Başlangıç'!$G$21 -> 8 | E8: - | F8: - | G8: -
A9: ='Başlangıç'!$A$23 -> Dumbbell Lunges | B9: =IF('Hafta 8'!$H$9+'Hafta 8'!$I$9+'Hafta 8'!$J$9>=42,'Hafta 8'!$B$9+'Başlangıç'!$F$23,'Hafta 8'!$B$9) -> 10 | C9: ='Başlangıç'!$H$23 -> 3x10-14 | D9: ='Başlangıç'!$G$23 -> 9 | E9: - | F9: - | G9: -
A10: ='Başlangıç'!$A$28 -> Crunch | B10: ='Başlangıç'!$E$28 -> vücut a. | C10: ='Başlangıç'!$H$28 -> 3xmax | D10: ='Başlangıç'!$G$28 -> 9 | E10: - | F10: - | G10: -
H11: 👆 her set için yaptığın tekrar sayılarını gir
A13: WORKOUT B | C13: 1 tekrar max tahmini 👉 | G13: =A15 -> Squat | I13: =MROUND((IF(J15="","",SUM((B15*(MAX(H15,I15,J15,K15))*0.0333)+B15))), 0.5) -> 0
A14: Egzersiz | B14: Kg | C14: Set x Tekrar | D14: RPE | E14: Isınma setleri | H14: Set 1 | I14: Set 2 | J14: Set 3 | K14: Set 4 | L14: Notlar
A15: ='Başlangıç'!$A$8 -> Squat | B15: =IF('Hafta 8'!$K$15>=5,(('Hafta 8'!$B$15)+('Başlangıç'!$F$8)),MROUND(('Hafta 8'!$B$15*0.9),2.5)) -> 12.5 | C15: ='Başlangıç'!$H$8 -> 4x5+ | D15: ='Başlangıç'!$G$8 | E15: =MROUND((B15*0.6),2.5) -> 7.5 | F15: =MROUND((B15*0.7),2.5) -> 10 | G15: =MROUND((B15*0.85),2.5) -> 10
A16: ='Başlangıç'!$A$14 -> Bench Press | B16: =IF('Hafta 8'!$J$16=10,(('Hafta 8'!$B$16)+('Başlangıç'!$F$14)),MROUND(('Hafta 8'!$B$16*0.9),2.5)) -> 10 | C16: ='Başlangıç'!$H$14 -> 3x10 | D16: ='Başlangıç'!$G$14 | E16: =MROUND((B16*0.6),2.5) -> 5 | F16: =MROUND((B16*0.85),2.5) -> 7.5 | G16: -
A17: ='Başlangıç'!$A$17 -> Negative Pull Ups | B17: ='Başlangıç'!$E$17 -> vücut a. | C17: ='Başlangıç'!$H$17 -> 3xmax | D17: ='Başlangıç'!$G$17 -> 9 | E17: - | F17: - | G17: -
A18: ='Başlangıç'!$A$20 -> Lateral Raises | B18: =IF('Hafta 8'!$H$18+'Hafta 8'!$I$18+'Hafta 8'!$J$18>=42,'Hafta 8'!$B$18+'Başlangıç'!$F$20,'Hafta 8'!$B$18) -> 5 | C18: ='Başlangıç'!$H$20 -> 3x10-14 | D18: ='Başlangıç'!$G$20 -> 9 | E18: - | F18: - | G18: -
A19: ='Başlangıç'!$A$27 -> Incline Dumbbell Curl | B19: =IF('Hafta 8'!$H$19+'Hafta 8'!$I$19+'Hafta 8'!$J$19>=36,'Hafta 8'!$B$19+'Başlangıç'!$F$27,'Hafta 8'!$B$19) -> 5 | C19: ='Başlangıç'!$H$27 -> 3x8-12 | D19: ='Başlangıç'!$G$27 -> 9 | E19: - | F19: - | G19: -
A20: ='Başlangıç'!$A$29 -> Leg Raises | B20: ='Başlangıç'!$E$29 -> vücut a. | C20: ='Başlangıç'!$H$29 -> 3xmax | D20: ='Başlangıç'!$G$29 -> 9 | E20: - | F20: - | G20: -
A23: WORKOUT C | C23: 1 tekrar max tahmini 👉 | G23: =A25 -> Over Head Press | I23: =MROUND((IF(J25="","",SUM((B25*(MAX(H25,I25,J25,K25))*0.0333)+B25))), 0.5) -> 0
A24: Egzersiz | B24: Kg | C24: Set x Tekrar | D24: RPE | E24: Isınma setleri | H24: Set 1 | I24: Set 2 | J24: Set 3 | K24: Set 4 | L24: Notlar
A25: ='Başlangıç'!$A$9 -> Over Head Press | B25: =IF('Hafta 8'!$K$25>=5,(('Hafta 8'!$B$25)+('Başlangıç'!$F$9)),MROUND(('Hafta 8'!$B$25*0.9),2.5)) -> 12.5 | C25: ='Başlangıç'!$H$9 -> 4x5+ | D25: ='Başlangıç'!$G$9 | E25: =MROUND((B25*0.6),2.5) -> 7.5 | F25: =MROUND((B25*0.7),2.5) -> 10 | G25: =MROUND((B25*0.85),2.5) -> 10
A26: ='Başlangıç'!$A$16 -> Squat | B26: =IF('Hafta 8'!$J$26=10,(('Hafta 8'!$B$26)+('Başlangıç'!$F$16)),MROUND(('Hafta 8'!$B$26*0.9),2.5)) -> 12.5 | C26: ='Başlangıç'!$H$16 -> 3x10 | D26: ='Başlangıç'!$G$16 | E26: =MROUND((B26*0.6),2.5) -> 7.5 | F26: =MROUND((B26*0.85),2.5) -> 10 | G26: -
A27: ='Başlangıç'!$A$15 -> Barbell Row | B27: =IF('Hafta 8'!$K$27=10,(('Hafta 8'!$B$27)+('Başlangıç'!$F$15)),MROUND(('Hafta 8'!$B$27*0.9),2.5)) -> 12.5 | C27: ='Başlangıç'!$H$15 -> 4x10 | D27: ='Başlangıç'!$G$15 | E27: =MROUND((B27*0.6),2.5) -> 7.5 | F27: =MROUND((B27*0.85),2.5) -> 10 | G27: -
A28: ='Başlangıç'!$A$22 -> Chest Fly Machine | B28: =IF('Hafta 8'!$H$28+'Hafta 8'!$I$28+'Hafta 8'!$J$28>=42,'Hafta 8'!$B$28+'Başlangıç'!$F$22,'Hafta 8'!$B$28) -> 27.5 | C28: ='Başlangıç'!$H$22 -> 3x10-14 | D28: ='Başlangıç'!$G$22 -> 8 | E28: - | F28: - | G28: -
A29: ='Başlangıç'!$A$26 -> Overhead Triceps Extension | B29: =IF('Hafta 8'!$H$29+'Hafta 8'!$I$29+'Hafta 8'!$J$29>=36,'Hafta 8'!$B$29+'Başlangıç'!$F$26,'Hafta 8'!$B$29) -> 15 | C29: ='Başlangıç'!$H$26 -> 3x8-12 | D29: ='Başlangıç'!$G$26 -> 9 | E29: - | F29: - | G29: -
A30: ='Başlangıç'!$A$30 -> Deadbug | B30: ='Başlangıç'!$E$30 -> vücut a. | C30: ='Başlangıç'!$H$30 -> 3xmax | D30: ='Başlangıç'!$G$30 -> 9 | E30: - | F30: - | G30: -

Sheet Hafta 10
A1: Vücut ağırlığı 👉 | B1: ='Başlangıç'!$B$3 -> 78.8
A3: WORKOUT A | C3: 1 tekrar max tahmini 👉 | G3: =A5 -> Bench Press | I3: =MROUND((IF(J5="","",SUM((B5*(MAX(H5,I5,J5,K5))*0.0333)+B5))), 0.5) -> 0
A4: Egzersiz | B4: Kg | C4: Set x Tekrar | D4: RPE | E4: Isınma setleri | H4: Set 1 | I4: Set 2 | J4: Set 3 | K4: Set 4 | L4: Notlar
A5: ='Başlangıç'!$A$7 -> Bench Press | B5: =IF('Hafta 9'!$K$5>=5,(('Hafta 9'!$B$5)+('Başlangıç'!$F$7)),MROUND(('Hafta 9'!$B$5*0.9),2.5)) -> 12.5 | C5: ='Başlangıç'!$H$7 -> 4x5+ | D5: ='Başlangıç'!$G$7 | E5: =MROUND((B5*0.6),2.5) -> 7.5 | F5: =MROUND((B5*0.7),2.5) -> 10 | G5: =MROUND((B5*0.85),2.5) -> 10 | M5: 👈 bu alanı not tutmak için kullanabilirsin
A6: ='Başlangıç'!$A$12 -> DB Shoulder Press | B6: =IF('Hafta 9'!$J$6=10,(('Hafta 9'!$B$6)+('Başlangıç'!$F$12)),MROUND(('Hafta 9'!$B$6*0.9),2.5)) -> 7.5 | C6: ='Başlangıç'!$H$12 -> 3x10 | D6: ='Başlangıç'!$G$12 | E6: =MROUND((B6*0.6),2.5) -> 5 | F6: =MROUND((B6*0.85),2.5) -> 7.5 | G6: -
A7: ='Başlangıç'!$A$13 -> Dumbbell Romanian Deadlift | B7: =IF('Hafta 9'!$J$7=8,(('Hafta 9'!$B$7)+('Başlangıç'!$F$13)),MROUND(('Hafta 9'!$B$7*0.9),2.5)) -> 12.5 | C7: ='Başlangıç'!$H$13 -> 3x8 | D7: ='Başlangıç'!$G$13 | E7: =MROUND((B7*0.6),2.5) -> 7.5 | F7: =MROUND((B7*0.85),2.5) -> 10 | G7: -
A8: ='Başlangıç'!$A$21 -> Lat Pulldown | B8: =IF('Hafta 9'!$H$8+'Hafta 9'!$I$8+'Hafta 9'!$J$8>=42,'Hafta 9'!$B$8+'Başlangıç'!$F$21,'Hafta 9'!$B$8) -> 32.5 | C8: ='Başlangıç'!$H$21 -> 3x10-14 | D8: ='Başlangıç'!$G$21 -> 8 | E8: - | F8: - | G8: -
A9: ='Başlangıç'!$A$23 -> Dumbbell Lunges | B9: =IF('Hafta 9'!$H$9+'Hafta 9'!$I$9+'Hafta 9'!$J$9>=42,'Hafta 9'!$B$9+'Başlangıç'!$F$23,'Hafta 9'!$B$9) -> 10 | C9: ='Başlangıç'!$H$23 -> 3x10-14 | D9: ='Başlangıç'!$G$23 -> 9 | E9: - | F9: - | G9: -
A10: ='Başlangıç'!$A$28 -> Crunch | B10: ='Başlangıç'!$E$28 -> vücut a. | C10: ='Başlangıç'!$H$28 -> 3xmax | D10: ='Başlangıç'!$G$28 -> 9 | E10: - | F10: - | G10: -
H11: 👆 her set için yaptığın tekrar sayılarını gir
A13: WORKOUT B | C13: 1 tekrar max tahmini 👉 | G13: =A15 -> Squat | I13: =MROUND((IF(J15="","",SUM((B15*(MAX(H15,I15,J15,K15))*0.0333)+B15))), 0.5) -> 0
A14: Egzersiz | B14: Kg | C14: Set x Tekrar | D14: RPE | E14: Isınma setleri | H14: Set 1 | I14: Set 2 | J14: Set 3 | K14: Set 4 | L14: Notlar
A15: ='Başlangıç'!$A$8 -> Squat | B15: =IF('Hafta 9'!$K$15>=5,(('Hafta 9'!$B$15)+('Başlangıç'!$F$8)),MROUND(('Hafta 9'!$B$15*0.9),2.5)) -> 12.5 | C15: ='Başlangıç'!$H$8 -> 4x5+ | D15: ='Başlangıç'!$G$8 | E15: =MROUND((B15*0.6),2.5) -> 7.5 | F15: =MROUND((B15*0.7),2.5) -> 10 | G15: =MROUND((B15*0.85),2.5) -> 10
A16: ='Başlangıç'!$A$14 -> Bench Press | B16: =IF('Hafta 9'!$J$16=10,(('Hafta 9'!$B$16)+('Başlangıç'!$F$14)),MROUND(('Hafta 9'!$B$16*0.9),2.5)) -> 10 | C16: ='Başlangıç'!$H$14 -> 3x10 | D16: ='Başlangıç'!$G$14 | E16: =MROUND((B16*0.6),2.5) -> 5 | F16: =MROUND((B16*0.85),2.5) -> 7.5 | G16: -
A17: ='Başlangıç'!$A$17 -> Negative Pull Ups | B17: ='Başlangıç'!$E$17 -> vücut a. | C17: ='Başlangıç'!$H$17 -> 3xmax | D17: ='Başlangıç'!$G$17 -> 9 | E17: - | F17: - | G17: -
A18: ='Başlangıç'!$A$20 -> Lateral Raises | B18: =IF('Hafta 9'!$H$18+'Hafta 9'!$I$18+'Hafta 9'!$J$18>=42,'Hafta 9'!$B$18+'Başlangıç'!$F$20,'Hafta 9'!$B$18) -> 5 | C18: ='Başlangıç'!$H$20 -> 3x10-14 | D18: ='Başlangıç'!$G$20 -> 9 | E18: - | F18: - | G18: -
A19: ='Başlangıç'!$A$27 -> Incline Dumbbell Curl | B19: =IF('Hafta 9'!$H$19+'Hafta 9'!$I$19+'Hafta 9'!$J$19>=36,'Hafta 9'!$B$19+'Başlangıç'!$F$27,'Hafta 9'!$B$19) -> 5 | C19: ='Başlangıç'!$H$27 -> 3x8-12 | D19: ='Başlangıç'!$G$27 -> 9 | E19: - | F19: - | G19: -
A20: ='Başlangıç'!$A$29 -> Leg Raises | B20: ='Başlangıç'!$E$29 -> vücut a. | C20: ='Başlangıç'!$H$29 -> 3xmax | D20: ='Başlangıç'!$G$29 -> 9 | E20: - | F20: - | G20: -
A23: WORKOUT C | C23: 1 tekrar max tahmini 👉 | G23: =A25 -> Over Head Press | I23: =MROUND((IF(J25="","",SUM((B25*(MAX(H25,I25,J25,K25))*0.0333)+B25))), 0.5) -> 0
A24: Egzersiz | B24: Kg | C24: Set x Tekrar | D24: RPE | E24: Isınma setleri | H24: Set 1 | I24: Set 2 | J24: Set 3 | K24: Set 4 | L24: Notlar
A25: ='Başlangıç'!$A$9 -> Over Head Press | B25: =IF('Hafta 9'!$K$25>=5,(('Hafta 9'!$B$25)+('Başlangıç'!$F$9)),MROUND(('Hafta 9'!$B$25*0.9),2.5)) -> 12.5 | C25: ='Başlangıç'!$H$9 -> 4x5+ | D25: ='Başlangıç'!$G$9 | E25: =MROUND((B25*0.6),2.5) -> 7.5 | F25: =MROUND((B25*0.7),2.5) -> 10 | G25: =MROUND((B25*0.85),2.5) -> 10
A26: ='Başlangıç'!$A$16 -> Squat | B26: =IF('Hafta 9'!$J$26=10,(('Hafta 9'!$B$26)+('Başlangıç'!$F$16)),MROUND(('Hafta 9'!$B$26*0.9),2.5)) -> 12.5 | C26: ='Başlangıç'!$H$16 -> 3x10 | D26: ='Başlangıç'!$G$16 | E26: =MROUND((B26*0.6),2.5) -> 7.5 | F26: =MROUND((B26*0.85),2.5) -> 10 | G26: -
A27: ='Başlangıç'!$A$15 -> Barbell Row | B27: =IF('Hafta 9'!$K$27=10,(('Hafta 9'!$B$27)+('Başlangıç'!$F$15)),MROUND(('Hafta 9'!$B$27*0.9),2.5)) -> 12.5 | C27: ='Başlangıç'!$H$15 -> 4x10 | D27: ='Başlangıç'!$G$15 | E27: =MROUND((B27*0.6),2.5) -> 7.5 | F27: =MROUND((B27*0.85),2.5) -> 10 | G27: -
A28: ='Başlangıç'!$A$22 -> Chest Fly Machine | B28: =IF('Hafta 9'!$H$28+'Hafta 9'!$I$28+'Hafta 9'!$J$28>=42,'Hafta 9'!$B$28+'Başlangıç'!$F$22,'Hafta 9'!$B$28) -> 27.5 | C28: ='Başlangıç'!$H$22 -> 3x10-14 | D28: ='Başlangıç'!$G$22 -> 8 | E28: - | F28: - | G28: -
A29: ='Başlangıç'!$A$26 -> Overhead Triceps Extension | B29: =IF('Hafta 9'!$H$29+'Hafta 9'!$I$29+'Hafta 9'!$J$29>=36,'Hafta 9'!$B$29+'Başlangıç'!$F$26,'Hafta 9'!$B$29) -> 15 | C29: ='Başlangıç'!$H$26 -> 3x8-12 | D29: ='Başlangıç'!$G$26 -> 9 | E29: - | F29: - | G29: -
A30: ='Başlangıç'!$A$30 -> Deadbug | B30: ='Başlangıç'!$E$30 -> vücut a. | C30: ='Başlangıç'!$H$30 -> 3xmax | D30: ='Başlangıç'!$G$30 -> 9 | E30: - | F30: - | G30: -

Sheet Hafta 11
A1: Vücut ağırlığı 👉 | B1: ='Başlangıç'!$B$3 -> 78.8
A3: WORKOUT A | C3: 1 tekrar max tahmini 👉 | G3: =A5 -> Bench Press | I3: =MROUND((IF(J5="","",SUM((B5*(MAX(H5,I5,J5,K5))*0.0333)+B5))), 0.5) -> 0
A4: Egzersiz | B4: Kg | C4: Set x Tekrar | D4: RPE | E4: Isınma setleri | H4: Set 1 | I4: Set 2 | J4: Set 3 | K4: Set 4 | L4: Notlar
